Workbook

Sheet 策略
A2: 军工 | B2: =军工!C41 -> 23200 | C2: =军工!D41 -> 1600 | D2: =B2/B17 -> 0.036394947 | F2: 43940 | G2: 50AHA | H2: 300价值 | I2: 中证500 | J2: 基本面50
A3: 银行 | B3: =银行!C41 -> 59301.555 | C3: =银行!D41 -> 4089.7624 | D3: =B3/B17 -> 0.093029179 | G3: PE 7.99/4.33% | H3: PE 7.34/14.84% | I3: PE 7.34/14.84% | J3: PE 8.47/23.84%
A4: 沪深300 | B4: =沪深300!C41 -> 39843.562 | C4: =沪深300!D41 -> 0 | D4: =B4/B17 -> 0.062504496 | G4: PB 0.93/2.07% | H4: PB 0.88/0.72% | I4: PB 0.88/0.72% | J4: PB 1.04/7%
A5: 证券 | B5: =证券!C41 -> 15937.425 | C5: =证券!D41 -> 0 | D5: =B5/B17 -> 0.025001798
A6: 基本面50 | B6: =基本面50!C41 -> 27093.622 | C6: =基本面50!D41 -> 1700 | D6: =B6/B17 -> 0.042503057
A7: 地产等权 | B7: =地产等权!C41 -> 38249.819 | C7: =地产等权!D41 -> 5040 | D7: =B7/B17 -> 0.060004316
A8: 300价值 | B8: ='300价值'!C41 -> 79687.123 | C8: ='300价值'!D41 -> 10500 | D8: =B8/B17 -> 0.12500899
A9: 50AHA | B9: ='50AH'!C41 -> 43031.046 | C9: ='50AH'!D41 -> 2700 | D9: =B9/B17 -> 0.067504856
A10: 基建 | B10: =基建!C41 -> 17858.362 | C10: =基建!D41 -> 2353.113 | D10: =B10/B17 -> 0.028015265
A11: 养老 | B11: =养老!C41 -> 43031.046 | C11: =养老!D41 -> 0 | D11: =B11/B17 -> 0.067504856
A12: 上证50 | B12: =上证50!C41 -> 63749.698 | C12: =上证50!D41 -> 0 | D12: =B12/B17 -> 0.10000719
A13: 中证500 | B13: =中证500!C41 -> 47812.274 | C13: =中证500!D41 -> 3000 | D13: =B13/B17 -> 0.075005395
A14: 中小板 | B14: =中小板!C41 -> 87655.835 | C14: =中小板!D41 -> 0 | D14: =B14/B17 -> 0.13750989
A15: 中证红利 | B15: =中证红利!C41 -> 19124.91 | C15: =中证红利!D41 -> 1200 | D15: =B15/B17 -> 0.030002158
A16: 恒生指数 | B16: =恒生指数!C41 -> 31874.849 | C16: =恒生指数!D41 -> 2000
B17: =SUM(B2:B16) -> 637451.13 | C17: =SUM(C2:C16) -> 34182.875 | D17: =C17/B17 -> 0.053624308

Sheet 300价值
A1: 43940
A2: PE 7.34/14.84%
A3: PB 0.88/0.72%
D4: 43946 | E4: 43957 | F4: 43963 | G4: 43971 | H4: 43986 | I4: 43993 | J4: 44022 | K4: 44028
A5: =A6*105% -> 6905.1096 | B5: =(A5-A13)/A13 -> 0.47745544 | C5: =C6*0.9 -> 172.18688
A6: =A7*105% -> 6576.2949 | B6: =(A6-A13)/A13 -> 0.40710042 | C6: =C7*0.9 -> 191.31876
A7: =A8*105% -> 6263.138 | B7: =(A7-A13)/A13 -> 0.34009564 | C7: =C8*0.9 -> 212.5764
A8: =A9*105% -> 5964.8933 | B8: =(A8-A13)/A13 -> 0.27628156 | C8: =C9*0.9 -> 236.196
A9: =A10*105% -> 5680.8508 | B9: =(A9-A13)/A13 -> 0.21550625 | C9: =C10*0.9 -> 262.44
A10: =A11*105% -> 5410.3341 | B10: =(A10-A13)/A13 -> 0.157625 | C10: =C11*0.9 -> 291.6
A11: =A12*105% -> 5152.6991 | B11: =(A11-A13)/A13 -> 0.1025 | C11: =C12*0.9 -> 324 | J11: 1000
A12: =A13*105% -> 4907.3325 | B12: =(A12-A13)/A13 -> 0.05 | C12: =C13*0.9 -> 360 | K12: 400
A13: 4673.65 | B13: =(A13-A13)/A13 -> 0 | C13: 400 | D13: 4252.2 | E13: 4484.34 | F13: 4497.22 | G13: 4469.32 | H13: 4499.96 | I13: 4438.02
A14: =A13*0.95 -> 4439.9675 | B14: =(A14-A13)/A13 -> -0.05 | C14: =C13*1.1 -> 440
A15: =A13*0.9 -> 4206.285 | B15: =(A15-A13)/A13 -> -0.1 | C15: =C13*1.2 -> 480
A16: =A13*0.85 -> 3972.6025 | B16: =(A16-A13)/A13 -> -0.15 | C16: =C13*1.3 -> 520
A17: =A13*0.8 -> 3738.92 | B17: =(A17-A13)/A13 -> -0.2 | C17: =C13*1.4 -> 560
A18: =A13*0.75 -> 3505.2375 | B18: =(A18-A13)/A13 -> -0.25 | C18: =C13*1.5 -> 600
A19: =A13*0.7 -> 3271.555 | B19: =(A19-A13)/A13 -> -0.3 | C19: =C13*1.6 -> 640
A20: =A13*0.65 -> 3037.8725 | B20: =(A20-A13)/A13 -> -0.35 | C20: =C13*1.7 -> 680
A21: =A13*0.6 -> 2804.19 | B21: =(A21-A13)/A13 -> -0.4 | C21: =C13*1.8 -> 720
A22: =A13*0.55 -> 2570.5075 | B22: =(A22-A13)/A13 -> -0.45 | C22: =C13*1.9 -> 760
A23: =A13*0.5 -> 2336.825 | B23: =(A23-A13)/A13 -> -0.5 | C23: =C13*2 -> 800
A24: =A13*0.45 -> 2103.1425 | B24: =(A24-A13)/A13 -> -0.55 | C24: =C13*2.1 -> 840
A25: =A13*0.4 -> 1869.46 | B25: =(A25-A13)/A13 -> -0.6 | C25: =C13*2.2 -> 880
A26: =A13*0.35 -> 1635.7775 | B26: =(A26-A13)/A13 -> -0.65 | C26: =C13*2.3 -> 920
A30: 4673.65 | B30: =(A30-A30)/A30 -> 0 | C30: 5000 | D30: =C30 -> 5000 | E30: 0 | F30: 0
A31: =A30*0.95 -> 4439.9675 | B31: =(A31-A30)/A30 -> -0.05 | C31: =C30*1.1 -> 5500 | D31: =D30*1.1 -> 5500 | E31: =(A31-A30)/A30*C30 -> -250 | F31: =E31/SUM(C30:C31) -> -0.023809524
A32: =A30*0.9 -> 4206.285 | B32: =(A32-A30)/A30 -> -0.1 | C32: =C31*1.1 -> 6050 | E32: =(A32-A30)/A30*C30+(A32-A31)/A31*C31 -> -789.47368 | F32: =E32/SUM(C30:C32) -> -0.047702337
A33: =A30*0.85 -> 3972.6025 | B33: =(A33-A30)/A30 -> -0.15 | C33: =C32*1.1 -> 6655 | E33: =(A33-A30)/A30*C30+(A33-A31)/A31*C31+(A33-A32)/A32*C32 -> -1665.0585 | F33: =E33/SUM(C30:C33) -> -0.071754298
A34: =A30*0.8 -> 3738.92 | B34: =(A34-A30)/A30 -> -0.2 | C34: =C33*1.1 -> 7320.5 | E34: =(A34-A30)/A30*C30+(A34-A31)/A31*C31+(A34-A32)/A32*C32+(A34-A33)/A33*C33 -> -2932.1139 | F34: =E34/SUM(C30:C34) -> -0.096054573
A35: =A30*0.75 -> 3505.2375 | B35: =(A35-A30)/A30 -> -0.25 | C35: =C34*1.1 -> 8052.55 | E35: =(A35-A30)/A30*C30+(A35-A31)/A31*C31+(A35-A32)/A32*C32+(A35-A33)/A33*C33+(A35-A34)/A34*C34 -> -4656.7005 | F35: =E35/SUM(C30:C35) -> -0.12070855
A36: =A30*0.7 -> 3271.555 | B36: =(A36-A30)/A30 -> -0.3 | C36: =C35*1.1 -> 8857.805 | E36: =(A36-A30)/A30*C30+(A36-A31)/A31*C31+(A36-A32)/A32*C32+(A36-A33)/A33*C33+(A36-A34)/A34*C34+(A36-A35)/A35*C35 -> -6918.1238 | F36: =E36/SUM(C30:C36) -> -0.14584166
A37: =A30*0.65 -> 3037.8725 | B37: =(A37-A30)/A30 -> -0.35 | C37: =C36*1.1 -> 9743.5855 | E37: =(A37-A30)/A30*C30+(A37-A31)/A31*C31+(A37-A32)/A32*C32+(A37-A33)/A33*C33+(A37-A34)/A34*C34+(A37-A35)/A35*C35+(A37-A36)/A36*C36 -> -9812.2475 | F37: =E37/SUM(C30:C37) -> -0.17160447
A38: =A30*0.6 -> 2804.19 | B38: =(A38-A30)/A30 -> -0.4 | C38: =C37*1.1 -> 10717.944 | E38: =(A38-A30)/A30*C30+(A38-A31)/A31*C31+(A38-A32)/A32*C32+(A38-A33)/A33*C33+(A38-A34)/A34*C34+(A38-A35)/A35*C35+(A38-A36)/A36*C36+(A38-A37)/A37*C37 -> -13455.878 | F38: =E38/SUM(C30:C38) -> -0.19817962
A39: =A30*0.55 -> 2570.5075 | B39: =(A39-A30)/A30 -> -0.45 | C39: =C38*1.1 -> 11789.738 | E39: =(A39-A30)/A30*C30+(A39-A31)/A31*C31+(A39-A32)/A32*C32+(A39-A33)/A33*C33+(A39-A34)/A34*C34+(A39-A35)/A35*C35+(A39-A36)/A36*C36+(A39-A37)/A37*C37+(A39-A38)/A38*C38 -> -17992.67 | F39: =E39/SUM(C30:C39) -> -0.22579144
C41: =SUM(C30:C39) -> 79687.123 | D41: =SUM(D30:D39) -> 10500

Sheet 沪深300
A1: 43940
A2: PE 11.38/34.76%
A3: PB 1.36/14.88%
A5: =A6*105% -> 5530.8397 | B5: =(A5-A13)/A13 -> 0.47745544 | C5: =C6*0.9 -> 172.18688
A6: =A7*105% -> 5267.4664 | B6: =(A6-A13)/A13 -> 0.40710042 | C6: =C7*0.9 -> 191.31876
A7: =A8*105% -> 5016.6346 | B7: =(A7-A13)/A13 -> 0.34009564 | C7: =C8*0.9 -> 212.5764
A8: =A9*105% -> 4777.7473 | B8: =(A8-A13)/A13 -> 0.27628156 | C8: =C9*0.9 -> 236.196
A9: =A10*105% -> 4550.2355 | B9: =(A9-A13)/A13 -> 0.21550625 | C9: =C10*0.9 -> 262.44
A10: =A11*105% -> 4333.5576 | B10: =(A10-A13)/A13 -> 0.157625 | C10: =C11*0.9 -> 291.6
A11: =A12*105% -> 4127.1977 | B11: =(A11-A13)/A13 -> 0.1025 | C11: =C12*0.9 -> 324
A12: =A13*105% -> 3930.6645 | B12: =(A12-A13)/A13 -> 0.05 | C12: =C13*0.9 -> 360
A13: 3743.49 | B13: =(A13-A13)/A13 -> 0 | C13: 400
A14: =A13*0.95 -> 3556.3155 | B14: =(A14-A13)/A13 -> -0.05 | C14: =C13*1.1 -> 440
A15: =A13*0.9 -> 3369.141 | B15: =(A15-A13)/A13 -> -0.1 | C15: =C13*1.2 -> 480
A16: =A13*0.85 -> 3181.9665 | B16: =(A16-A13)/A13 -> -0.15 | C16: =C13*1.3 -> 520
A17: =A13*0.8 -> 2994.792 | B17: =(A17-A13)/A13 -> -0.2 | C17: =C13*1.4 -> 560
A18: =A13*0.75 -> 2807.6175 | B18: =(A18-A13)/A13 -> -0.25 | C18: =C13*1.5 -> 600
A19: =A13*0.7 -> 2620.443 | B19: =(A19-A13)/A13 -> -0.3 | C19: =C13*1.6 -> 640
A20: =A13*0.65 -> 2433.2685 | B20: =(A20-A13)/A13 -> -0.35 | C20: =C13*1.7 -> 680
A21: =A13*0.6 -> 2246.094 | B21: =(A21-A13)/A13 -> -0.4 | C21: =C13*1.8 -> 720
A22: =A13*0.55 -> 2058.9195 | B22: =(A22-A13)/A13 -> -0.45 | C22: =C13*1.9 -> 760
A23: =A13*0.5 -> 1871.745 | B23: =(A23-A13)/A13 -> -0.5 | C23: =C13*2 -> 800
A24: =A13*0.45 -> 1684.5705 | B24: =(A24-A13)/A13 -> -0.55 | C24: =C13*2.1 -> 840
A25: =A13*0.4 -> 1497.396 | B25: =(A25-A13)/A13 -> -0.6 | C25: =C13*2.2 -> 880
A26: =A13*0.35 -> 1310.2215 | B26: =(A26-A13)/A13 -> -0.65 | C26: =C13*2.3 -> 920
A30: 3743.49 | B30: =(A30-A30)/A30 -> 0 | C30: 2500 | E30: 0 | F30: 0
A31: =A30*0.95 -> 3556.3155 | B31: =(A31-A30)/A30 -> -0.05 | C31: =C30*1.1 -> 2750 | E31: =(A31-A30)/A30*C30 -> -125 | F31: =E31/SUM(C30:C31) -> -0.023809524
A32: =A30*0.9 -> 3369.141 | B32: =(A32-A30)/A30 -> -0.1 | C32: =C31*1.1 -> 3025 | E32: =(A32-A30)/A30*C30+(A32-A31)/A31*C31 -> -394.73684 | F32: =E32/SUM(C30:C32) -> -0.047702337
A33: =A30*0.85 -> 3181.9665 | B33: =(A33-A30)/A30 -> -0.15 | C33: =C32*1.1 -> 3327.5 | E33: =(A33-A30)/A30*C30+(A33-A31)/A31*C31+(A33-A32)/A32*C32 -> -832.52924 | F33: =E33/SUM(C30:C33) -> -0.071754298
A34: =A30*0.8 -> 2994.792 | B34: =(A34-A30)/A30 -> -0.2 | C34: =C33*1.1 -> 3660.25 | E34: =(A34-A30)/A30*C30+(A34-A31)/A31*C31+(A34-A32)/A32*C32+(A34-A33)/A33*C33 -> -1466.0569 | F34: =E34/SUM(C30:C34) -> -0.096054573
A35: =A30*0.75 -> 2807.6175 | B35: =(A35-A30)/A30 -> -0.25 | C35: =C34*1.1 -> 4026.275 | E35: =(A35-A30)/A30*C30+(A35-A31)/A31*C31+(A35-A32)/A32*C32+(A35-A33)/A33*C33+(A35-A34)/A34*C34 -> -2328.3502 | F35: =E35/SUM(C30:C35) -> -0.12070855
A36: =A30*0.7 -> 2620.443 | B36: =(A36-A30)/A30 -> -0.3 | C36: =C35*1.1 -> 4428.9025 | E36: =(A36-A30)/A30*C30+(A36-A31)/A31*C31+(A36-A32)/A32*C32+(A36-A33)/A33*C33+(A36-A34)/A34*C34+(A36-A35)/A35*C35 -> -3459.0619 | F36: =E36/SUM(C30:C36) -> -0.14584166
A37: =A30*0.65 -> 2433.2685 | B37: =(A37-A30)/A30 -> -0.35 | C37: =C36*1.1 -> 4871.7927 | E37: =(A37-A30)/A30*C30+(A37-A31)/A31*C31+(A37-A32)/A32*C32+(A37-A33)/A33*C33+(A37-A34)/A34*C34+(A37-A35)/A35*C35+(A37-A36)/A36*C36 -> -4906.1237 | F37: =E37/SUM(C30:C37) -> -0.17160447
A38: =A30*0.6 -> 2246.094 | B38: =(A38-A30)/A30 -> -0.4 | C38: =C37*1.1 -> 5358.972 | E38: =(A38-A30)/A30*C30+(A38-A31)/A31*C31+(A38-A32)/A32*C32+(A38-A33)/A33*C33+(A38-A34)/A34*C34+(A38-A35)/A35*C35+(A38-A36)/A36*C36+(A38-A37)/A37*C37 -> -6727.9388 | F38: =E38/SUM(C30:C38) -> -0.19817962
A39: =A30*0.55 -> 2058.9195 | B39: =(A39-A30)/A30 -> -0.45 | C39: =C38*1.1 -> 5894.8692 | E39: =(A39-A30)/A30*C30+(A39-A31)/A31*C31+(A39-A32)/A32*C32+(A39-A33)/A33*C33+(A39-A34)/A34*C34+(A39-A35)/A35*C35+(A39-A36)/A36*C36+(A39-A37)/A37*C37+(A39-A38)/A38*C38 -> -8996.335 | F39: =E39/SUM(C30:C39) -> -0.22579144
C41: =SUM(C30:C39) -> 39843.562 | D41: =SUM(D30:D39) -> 0

Sheet 基本面50
A1: 43940
A2: PE 8.47/23.84%
A3: PB 1.04/7%
D4: 43942 | E4: 43957 | F4: 43963 | G4: 43971 | H4: 43979 | I4: 43986 | J4: 43993 | K4: 44022
A5: =A6*105% -> 5723.1748 | B5: =(A5-A13)/A13 -> 0.47745544 | C5: =C6*0.9 -> 172.18688
A6: =A7*105% -> 5450.6427 | B6: =(A6-A13)/A13 -> 0.40710042 | C6: =C7*0.9 -> 191.31876
A7: =A8*105% -> 5191.0883 | B7: =(A7-A13)/A13 -> 0.34009564 | C7: =C8*0.9 -> 212.5764
A8: =A9*105% -> 4943.8936 | B8: =(A8-A13)/A13 -> 0.27628156 | C8: =C9*0.9 -> 236.196
A9: =A10*105% -> 4708.4701 | B9: =(A9-A13)/A13 -> 0.21550625 | C9: =C10*0.9 -> 262.44
A10: =A11*105% -> 4484.2572 | B10: =(A10-A13)/A13 -> 0.157625 | C10: =C11*0.9 -> 291.6 | K10: 1000
A11: =A12*105% -> 4270.7212 | B11: =(A11-A13)/A13 -> 0.1025 | C11: =C12*0.9 -> 324
A12: =A13*105% -> 4067.3535 | B12: =(A12-A13)/A13 -> 0.05 | C12: =C13*0.9 -> 360
A13: 3873.67 | B13: =(A13-A13)/A13 -> 0 | C13: 400 | D13: 3884.55 | E13: 3963.32 | F13: 3969.42 | G13: 3932.39 | H13: 3889 | I13: 3943 | J13: 3897
A14: =A13*0.95 -> 3679.9865 | B14: =(A14-A13)/A13 -> -0.05 | C14: =C13*1.1 -> 440
A15: =A13*0.9 -> 3486.303 | B15: =(A15-A13)/A13 -> -0.1 | C15: =C13*1.2 -> 480
A16: =A13*0.85 -> 3292.6195 | B16: =(A16-A13)/A13 -> -0.15 | C16: =C13*1.3 -> 520
A17: =A13*0.8 -> 3098.936 | B17: =(A17-A13)/A13 -> -0.2 | C17: =C13*1.4 -> 560
A18: =A13*0.75 -> 2905.2525 | B18: =(A18-A13)/A13 -> -0.25 | C18: =C13*1.5 -> 600
A19: =A13*0.7 -> 2711.569 | B19: =(A19-A13)/A13 -> -0.3 | C19: =C13*1.6 -> 640
A20: =A13*0.65 -> 2517.8855 | B20: =(A20-A13)/A13 -> -0.35 | C20: =C13*1.7 -> 680
A21: =A13*0.6 -> 2324.202 | B21: =(A21-A13)/A13 -> -0.4 | C21: =C13*1.8 -> 720
A22: =A13*0.55 -> 2130.5185 | B22: =(A22-A13)/A13 -> -0.45 | C22: =C13*1.9 -> 760
A23: =A13*0.5 -> 1936.835 | B23: =(A23-A13)/A13 -> -0.5 | C23: =C13*2 -> 800
A24: =A13*0.45 -> 1743.1515 | B24: =(A24-A13)/A13 -> -0.55 | C24: =C13*2.1 -> 840
A25: =A13*0.4 -> 1549.468 | B25: =(A25-A13)/A13 -> -0.6 | C25: =C13*2.2 -> 880
A26: =A13*0.35 -> 1355.7845 | B26: =(A26-A13)/A13 -> -0.65 | C26: =C13*2.3 -> 920
A30: 3873.67 | B30: =(A30-A30)/A30 -> 0 | C30: 1700 | D30: =C30 -> 1700 | E30: 0 | F30: 0
A31: =A30*0.95 -> 3679.9865 | B31: =(A31-A30)/A30 -> -0.05 | C31: =C30*1.1 -> 1870 | E31: =(A31-A30)/A30*C30 -> -85 | F31: =E31/SUM(C30:C31) -> -0.023809524
A32: =A30*0.9 -> 3486.303 | B32: =(A32-A30)/A30 -> -0.1 | C32: =C31*1.1 -> 2057 | E32: =(A32-A30)/A30*C30+(A32-A31)/A31*C31 -> -268.42105 | F32: =E32/SUM(C30:C32) -> -0.047702337
A33: =A30*0.85 -> 3292.6195 | B33: =(A33-A30)/A30 -> -0.15 | C33: =C32*1.1 -> 2262.7 | E33: =(A33-A30)/A30*C30+(A33-A31)/A31*C31+(A33-A32)/A32*C32 -> -566.11988 | F33: =E33/SUM(C30:C33) -> -0.071754298
A34: =A30*0.8 -> 3098.936 | B34: =(A34-A30)/A30 -> -0.2 | C34: =C33*1.1 -> 2488.97 | E34: =(A34-A30)/A30*C30+(A34-A31)/A31*C31+(A34-A32)/A32*C32+(A34-A33)/A33*C33 -> -996.91871 | F34: =E34/SUM(C30:C34) -> -0.096054573
A35: =A30*0.75 -> 2905.2525 | B35: =(A35-A30)/A30 -> -0.25 | C35: =C34*1.1 -> 2737.867 | E35: =(A35-A30)/A30*C30+(A35-A31)/A31*C31+(A35-A32)/A32*C32+(A35-A33)/A33*C33+(A35-A34)/A34*C34 -> -1583.2782 | F35: =E35/SUM(C30:C35) -> -0.12070855
A36: =A30*0.7 -> 2711.569 | B36: =(A36-A30)/A30 -> -0.3 | C36: =C35*1.1 -> 3011.6537 | E36: =(A36-A30)/A30*C30+(A36-A31)/A31*C31+(A36-A32)/A32*C32+(A36-A33)/A33*C33+(A36-A34)/A34*C34+(A36-A35)/A35*C35 -> -2352.1621 | F36: =E36/SUM(C30:C36) -> -0.14584166
A37: =A30*0.65 -> 2517.8855 | B37: =(A37-A30)/A30 -> -0.35 | C37: =C36*1.1 -> 3312.8191 | E37: =(A37-A30)/A30*C30+(A37-A31)/A31*C31+(A37-A32)/A32*C32+(A37-A33)/A33*C33+(A37-A34)/A34*C34+(A37-A35)/A35*C35+(A37-A36)/A36*C36 -> -3336.1641 | F37: =E37/SUM(C30:C37) -> -0.17160447
A38: =A30*0.6 -> 2324.202 | B38: =(A38-A30)/A30 -> -0.4 | C38: =C37*1.1 -> 3644.101 | E38: =(A38-A30)/A30*C30+(A38-A31)/A31*C31+(A38-A32)/A32*C32+(A38-A33)/A33*C33+(A38-A34)/A34*C34+(A38-A35)/A35*C35+(A38-A36)/A36*C36+(A38-A37)/A37*C37 -> -4574.9984 | F38: =E38/SUM(C30:C38) -> -0.19817962
A39: =A30*0.55 -> 2130.5185 | B39: =(A39-A30)/A30 -> -0.45 | C39: =C38*1.1 -> 4008.5111 | E39: =(A39-A30)/A30*C30+(A39-A31)/A31*C31+(A39-A32)/A32*C32+(A39-A33)/A33*C33+(A39-A34)/A34*C34+(A39-A35)/A35*C35+(A39-A36)/A36*C36+(A39-A37)/A37*C37+(A39-A38)/A38*C38 -> -6117.5078 | F39: =E39/SUM(C30:C39) -> -0.22579144
C41: =SUM(C30:C39) -> 27093.622 | D41: =SUM(D30:D39) -> 1700

Sheet 50AH
A1: 43940
A2: PE 7.99/4.33%
A3: PB 0.93/2.07%
D4: 43942 | E4: 43958 | F4: 43963 | G4: 43971 | H4: 43978 | I4: 43979 | J4: 43986
A5: =A6*105% -> 7778.0346 | B5: =(A5-A13)/A13 -> 0.47745544 | C5: =C6*0.9 -> 172.18688
A6: =A7*105% -> 7407.652 | B6: =(A6-A13)/A13 -> 0.40710042 | C6: =C7*0.9 -> 191.31876
A7: =A8*105% -> 7054.9067 | B7: =(A7-A13)/A13 -> 0.34009564 | C7: =C8*0.9 -> 212.5764
A8: =A9*105% -> 6718.9588 | B8: =(A8-A13)/A13 -> 0.27628156 | C8: =C9*0.9 -> 236.196
A9: =A10*105% -> 6399.0083 | B9: =(A9-A13)/A13 -> 0.21550625 | C9: =C10*0.9 -> 262.44
A10: =A11*105% -> 6094.2937 | B10: =(A10-A13)/A13 -> 0.157625 | C10: =C11*0.9 -> 291.6
A11: =A12*105% -> 5804.0892 | B11: =(A11-A13)/A13 -> 0.1025 | C11: =C12*0.9 -> 324
A12: =A13*105% -> 5527.704 | B12: =(A12-A13)/A13 -> 0.05 | C12: =C13*0.9 -> 360
A13: 5264.48 | B13: =(A13-A13)/A13 -> 0 | C13: 400 | D13: 5196.03 | E13: 5323.32 | F13: 5360.44 | G13: 5337.7 | H13: 5218.85 | I13: 5241 | J13: 5406
A14: =A13*0.95 -> 5001.256 | B14: =(A14-A13)/A13 -> -0.05 | C14: =C13*1.1 -> 440
A15: =A13*0.9 -> 4738.032 | B15: =(A15-A13)/A13 -> -0.1 | C15: =C13*1.2 -> 480
A16: =A13*0.85 -> 4474.808 | B16: =(A16-A13)/A13 -> -0.15 | C16: =C13*1.3 -> 520
A17: =A13*0.8 -> 4211.584 | B17: =(A17-A13)/A13 -> -0.2 | C17: =C13*1.4 -> 560
A18: =A13*0.75 -> 3948.36 | B18: =(A18-A13)/A13 -> -0.25 | C18: =C13*1.5 -> 600
A19: =A13*0.7 -> 3685.136 | B19: =(A19-A13)/A13 -> -0.3 | C19: =C13*1.6 -> 640
A20: =A13*0.65 -> 3421.912 | B20: =(A20-A13)/A13 -> -0.35 | C20: =C13*1.7 -> 680
A21: =A13*0.6 -> 3158.688 | B21: =(A21-A13)/A13 -> -0.4 | C21: =C13*1.8 -> 720
A22: =A13*0.55 -> 2895.464 | B22: =(A22-A13)/A13 -> -0.45 | C22: =C13*1.9 -> 760
A23: =A13*0.5 -> 2632.24 | B23: =(A23-A13)/A13 -> -0.5 | C23: =C13*2 -> 800
A24: =A13*0.45 -> 2369.016 | B24: =(A24-A13)/A13 -> -0.55 | C24: =C13*2.1 -> 840
A25: =A13*0.4 -> 2105.792 | B25: =(A25-A13)/A13 -> -0.6 | C25: =C13*2.2 -> 880
A26: =A13*0.35 -> 1842.568 | B26: =(A26-A13)/A13 -> -0.65 | C26: =C13*2.3 -> 920
A30: 5264.48 | B30: =(A30-A30)/A30 -> 0 | C30: 2700 | D30: =C30 -> 2700 | E30: 0 | F30: 0
A31: =A30*0.95 -> 5001.256 | B31: =(A31-A30)/A30 -> -0.05 | C31: =C30*1.1 -> 2970 | E31: =(A31-A30)/A30*C30 -> -135 | F31: =E31/SUM(C30:C31) -> -0.023809524
A32: =A30*0.9 -> 4738.032 | B32: =(A32-A30)/A30 -> -0.1 | C32: =C31*1.1 -> 3267 | E32: =(A32-A30)/A30*C30+(A32-A31)/A31*C31 -> -426.31579 | F32: =E32/SUM(C30:C32) -> -0.047702337
A33: =A30*0.85 -> 4474.808 | B33: =(A33-A30)/A30 -> -0.15 | C33: =C32*1.1 -> 3593.7 | E33: =(A33-A30)/A30*C30+(A33-A31)/A31*C31+(A33-A32)/A32*C32 -> -899.13158 | F33: =E33/SUM(C30:C33) -> -0.071754298
A34: =A30*0.8 -> 4211.584 | B34: =(A34-A30)/A30 -> -0.2 | C34: =C33*1.1 -> 3953.07 | E34: =(A34-A30)/A30*C30+(A34-A31)/A31*C31+(A34-A32)/A32*C32+(A34-A33)/A33*C33 -> -1583.3415 | F34: =E34/SUM(C30:C34) -> -0.096054573
A35: =A30*0.75 -> 3948.36 | B35: =(A35-A30)/A30 -> -0.25 | C35: =C34*1.1 -> 4348.377 | E35: =(A35-A30)/A30*C30+(A35-A31)/A31*C31+(A35-A32)/A32*C32+(A35-A33)/A33*C33+(A35-A34)/A34*C34 -> -2514.6183 | F35: =E35/SUM(C30:C35) -> -0.12070855
A36: =A30*0.7 -> 3685.136 | B36: =(A36-A30)/A30 -> -0.3 | C36: =C35*1.1 -> 4783.2147 | E36: =(A36-A30)/A30*C30+(A36-A31)/A31*C31+(A36-A32)/A32*C32+(A36-A33)/A33*C33+(A36-A34)/A34*C34+(A36-A35)/A35*C35 -> -3735.7869 | F36: =E36/SUM(C30:C36) -> -0.14584166
A37: =A30*0.65 -> 3421.912 | B37: =(A37-A30)/A30 -> -0.35 | C37: =C36*1.1 -> 5261.5362 | E37: =(A37-A30)/A30*C30+(A37-A31)/A31*C31+(A37-A32)/A32*C32+(A37-A33)/A33*C33+(A37-A34)/A34*C34+(A37-A35)/A35*C35+(A37-A36)/A36*C36 -> -5298.6136 | F37: =E37/SUM(C30:C37) -> -0.17160447
A38: =A30*0.6 -> 3158.688 | B38: =(A38-A30)/A30 -> -0.4 | C38: =C37*1.1 -> 5787.6898 | E38: =(A38-A30)/A30*C30+(A38-A31)/A31*C31+(A38-A32)/A32*C32+(A38-A33)/A33*C33+(A38-A34)/A34*C34+(A38-A35)/A35*C35+(A38-A36)/A36*C36+(A38-A37)/A37*C37 -> -7266.174 | F38: =E38/SUM(C30:C38) -> -0.19817962
A39: =A30*0.55 -> 2895.464 | B39: =(A39-A30)/A30 -> -0.45 | C39: =C38*1.1 -> 6366.4588 | E39: =(A39-A30)/A30*C30+(A39-A31)/A31*C31+(A39-A32)/A32*C32+(A39-A33)/A33*C33+(A39-A34)/A34*C34+(A39-A35)/A35*C35+(A39-A36)/A36*C36+(A39-A37)/A37*C37+(A39-A38)/A38*C38 -> -9716.0418 | F39: =E39/SUM(C30:C39) -> -0.22579144
C41: =SUM(C30:C39) -> 43031.046 | D41: =SUM(D30:D39) -> 2700

Sheet 上证50
D1: 43940
D2: PE 8.86/18.48%
D3: PB 1.09/1.84%
A5: =A6*105% -> 4150.2905 | B5: =(A5-A13)/A13 -> 0.47745544 | C5: =C6*0.9 -> 172.18688
A6: =A7*105% -> 3952.6577 | B6: =(A6-A13)/A13 -> 0.40710042 | C6: =C7*0.9 -> 191.31876
A7: =A8*105% -> 3764.4359 | B7: =(A7-A13)/A13 -> 0.34009564 | C7: =C8*0.9 -> 212.5764
A8: =A9*105% -> 3585.177 | B8: =(A8-A13)/A13 -> 0.27628156 | C8: =C9*0.9 -> 236.196
A9: =A10*105% -> 3414.4543 | B9: =(A9-A13)/A13 -> 0.21550625 | C9: =C10*0.9 -> 262.44
A10: =A11*105% -> 3251.8612 | B10: =(A10-A13)/A13 -> 0.157625 | C10: =C11*0.9 -> 291.6
A11: =A12*105% -> 3097.0107 | B11: =(A11-A13)/A13 -> 0.1025 | C11: =C12*0.9 -> 324
A12: =A13*105% -> 2949.534 | B12: =(A12-A13)/A13 -> 0.05 | C12: =C13*0.9 -> 360
A13: 2809.08 | B13: =(A13-A13)/A13 -> 0 | C13: 400
A14: =A13*0.95 -> 2668.626 | B14: =(A14-A13)/A13 -> -0.05 | C14: =C13*1.1 -> 440
A15: =A13*0.9 -> 2528.172 | B15: =(A15-A13)/A13 -> -0.1 | C15: =C13*1.2 -> 480
A16: =A13*0.85 -> 2387.718 | B16: =(A16-A13)/A13 -> -0.15 | C16: =C13*1.3 -> 520
A17: =A13*0.8 -> 2247.264 | B17: =(A17-A13)/A13 -> -0.2 | C17: =C13*1.4 -> 560
A18: =A13*0.75 -> 2106.81 | B18: =(A18-A13)/A13 -> -0.25 | C18: =C13*1.5 -> 600
A19: =A13*0.7 -> 1966.356 | B19: =(A19-A13)/A13 -> -0.3 | C19: =C13*1.6 -> 640
A20: =A13*0.65 -> 1825.902 | B20: =(A20-A13)/A13 -> -0.35 | C20: =C13*1.7 -> 680
A21: =A13*0.6 -> 1685.448 | B21: =(A21-A13)/A13 -> -0.4 | C21: =C13*1.8 -> 720
A22: =A13*0.55 -> 1544.994 | B22: =(A22-A13)/A13 -> -0.45 | C22: =C13*1.9 -> 760
A23: =A13*0.5 -> 1404.54 | B23: =(A23-A13)/A13 -> -0.5 | C23: =C13*2 -> 800
A24: =A13*0.45 -> 1264.086 | B24: =(A24-A13)/A13 -> -0.55 | C24: =C13*2.1 -> 840
A25: =A13*0.4 -> 1123.632 | B25: =(A25-A13)/A13 -> -0.6 | C25: =C13*2.2 -> 880
A26: =A13*0.35 -> 983.178 | B26: =(A26-A13)/A13 -> -0.65 | C26: =C13*2.3 -> 920
A30: 2809.08 | B30: =(A30-A30)/A30 -> 0 | C30: 4000 | E30: 0 | F30: 0
A31: =A30*0.95 -> 2668.626 | B31: =(A31-A30)/A30 -> -0.05 | C31: =C30*1.1 -> 4400 | E31: =(A31-A30)/A30*C30 -> -200 | F31: =E31/SUM(C30:C31) -> -0.023809524
A32: =A30*0.9 -> 2528.172 | B32: =(A32-A30)/A30 -> -0.1 | C32: =C31*1.1 -> 4840 | E32: =(A32-A30)/A30*C30+(A32-A31)/A31*C31 -> -631.57895 | F32: =E32/SUM(C30:C32) -> -0.047702337
A33: =A30*0.85 -> 2387.718 | B33: =(A33-A30)/A30 -> -0.15 | C33: =C32*1.1 -> 5324 | E33: =(A33-A30)/A30*C30+(A33-A31)/A31*C31+(A33-A32)/A32*C32 -> -1332.0468 | F33: =E33/SUM(C30:C33) -> -0.071754298
A34: =A30*0.8 -> 2247.264 | B34: =(A34-A30)/A30 -> -0.2 | C34: =C33*1.1 -> 5856.4 | E34: =(A34-A30)/A30*C30+(A34-A31)/A31*C31+(A34-A32)/A32*C32+(A34-A33)/A33*C33 -> -2345.6911 | F34: =E34/SUM(C30:C34) -> -0.096054573
A35: =A30*0.75 -> 2106.81 | B35: =(A35-A30)/A30 -> -0.25 | C35: =C34*1.1 -> 6442.04 | E35: =(A35-A30)/A30*C30+(A35-A31)/A31*C31+(A35-A32)/A32*C32+(A35-A33)/A33*C33+(A35-A34)/A34*C34 -> -3725.3604 | F35: =E35/SUM(C30:C35) -> -0.12070855
A36: =A30*0.7 -> 1966.356 | B36: =(A36-A30)/A30 -> -0.3 | C36: =C35*1.1 -> 7086.244 | E36: =(A36-A30)/A30*C30+(A36-A31)/A31*C31+(A36-A32)/A32*C32+(A36-A33)/A33*C33+(A36-A34)/A34*C34+(A36-A35)/A35*C35 -> -5534.499 | F36: =E36/SUM(C30:C36) -> -0.14584166
A37: =A30*0.65 -> 1825.902 | B37: =(A37-A30)/A30 -> -0.35 | C37: =C36*1.1 -> 7794.8684 | E37: =(A37-A30)/A30*C30+(A37-A31)/A31*C31+(A37-A32)/A32*C32+(A37-A33)/A33*C33+(A37-A34)/A34*C34+(A37-A35)/A35*C35+(A37-A36)/A36*C36 -> -7849.798 | F37: =E37/SUM(C30:C37) -> -0.17160447
A38: =A30*0.6 -> 1685.448 | B38: =(A38-A30)/A30 -> -0.4 | C38: =C37*1.1 -> 8574.3552 | E38: =(A38-A30)/A30*C30+(A38-A31)/A31*C31+(A38-A32)/A32*C32+(A38-A33)/A33*C33+(A38-A34)/A34*C34+(A38-A35)/A35*C35+(A38-A36)/A36*C36+(A38-A37)/A37*C37 -> -10764.702 | F38: =E38/SUM(C30:C38) -> -0.19817962
A39: =A30*0.55 -> 1544.994 | B39: =(A39-A30)/A30 -> -0.45 | C39: =C38*1.1 -> 9431.7908 | E39: =(A39-A30)/A30*C30+(A39-A31)/A31*C31+(A39-A32)/A32*C32+(A39-A33)/A33*C33+(A39-A34)/A34*C34+(A39-A35)/A35*C35+(A39-A36)/A36*C36+(A39-A37)/A37*C37+(A39-A38)/A38*C38 -> -14394.136 | F39: =E39/SUM(C30:C39) -> -0.22579144
C41: =SUM(C30:C39) -> 63749.698 | D41: =SUM(D30:D39) -> 0

Sheet 中证500
A1: 43940
A2: PE 26.37/21.12%
A3: PB 1.83/10.52%
D4: 43942 | E4: 43969 | F4: 43978
A5: =A6*105% -> 7901.1067 | B5: =(A5-A13)/A13 -> 0.47745544 | C5: =C6*0.9 -> 172.18688
A6: =A7*105% -> 7524.8635 | B6: =(A6-A13)/A13 -> 0.40710042 | C6: =C7*0.9 -> 191.31876
A7: =A8*105% -> 7166.5367 | B7: =(A7-A13)/A13 -> 0.34009564 | C7: =C8*0.9 -> 212.5764
A8: =A9*105% -> 6825.273 | B8: =(A8-A13)/A13 -> 0.27628156 | C8: =C9*0.9 -> 236.196
A9: =A10*105% -> 6500.26 | B9: =(A9-A13)/A13 -> 0.21550625 | C9: =C10*0.9 -> 262.44
A10: =A11*105% -> 6190.7238 | B10: =(A10-A13)/A13 -> 0.157625 | C10: =C11*0.9 -> 291.6
A11: =A12*105% -> 5895.9275 | B11: =(A11-A13)/A13 -> 0.1025 | C11: =C12*0.9 -> 324
A12: =A13*105% -> 5615.169 | B12: =(A12-A13)/A13 -> 0.05 | C12: =C13*0.9 -> 360
A13: 5347.78 | B13: =(A13-A13)/A13 -> 0 | C13: 400 | D13: 5242.88 | E13: 5478.82 | F13: 5369.5
A14: =A13*0.95 -> 5080.391 | B14: =(A14-A13)/A13 -> -0.05 | C14: =C13*1.1 -> 440
A15: =A13*0.9 -> 4813.002 | B15: =(A15-A13)/A13 -> -0.1 | C15: =C13*1.2 -> 480
A16: =A13*0.85 -> 4545.613 | B16: =(A16-A13)/A13 -> -0.15 | C16: =C13*1.3 -> 520
A17: =A13*0.8 -> 4278.224 | B17: =(A17-A13)/A13 -> -0.2 | C17: =C13*1.4 -> 560
A18: =A13*0.75 -> 4010.835 | B18: =(A18-A13)/A13 -> -0.25 | C18: =C13*1.5 -> 600
A19: =A13*0.7 -> 3743.446 | B19: =(A19-A13)/A13 -> -0.3 | C19: =C13*1.6 -> 640
A20: =A13*0.65 -> 3476.057 | B20: =(A20-A13)/A13 -> -0.35 | C20: =C13*1.7 -> 680
A21: =A13*0.6 -> 3208.668 | B21: =(A21-A13)/A13 -> -0.4 | C21: =C13*1.8 -> 720
A22: =A13*0.55 -> 2941.279 | B22: =(A22-A13)/A13 -> -0.45 | C22: =C13*1.9 -> 760
A23: =A13*0.5 -> 2673.89 | B23: =(A23-A13)/A13 -> -0.5 | C23: =C13*2 -> 800
A24: =A13*0.45 -> 2406.501 | B24: =(A24-A13)/A13 -> -0.55 | C24: =C13*2.1 -> 840
A25: =A13*0.4 -> 2139.112 | B25: =(A25-A13)/A13 -> -0.6 | C25: =C13*2.2 -> 880
A26: =A13*0.35 -> 1871.723 | B26: =(A26-A13)/A13 -> -0.65 | C26: =C13*2.3 -> 920
A30: 5347.78 | B30: =(A30-A30)/A30 -> 0 | C30: 3000 | D30: =C30 -> 3000 | E30: 0 | F30: 0
A31: =A30*0.95 -> 5080.391 | B31: =(A31-A30)/A30 -> -0.05 | C31: =C30*1.1 -> 3300 | E31: =(A31-A30)/A30*C30 -> -150 | F31: =E31/SUM(C30:C31) -> -0.023809524
A32: =A30*0.9 -> 4813.002 | B32: =(A32-A30)/A30 -> -0.1 | C32: =C31*1.1 -> 3630 | E32: =(A32-A30)/A30*C30+(A32-A31)/A31*C31 -> -473.68421 | F32: =E32/SUM(C30:C32) -> -0.047702337
A33: =A30*0.85 -> 4545.613 | B33: =(A33-A30)/A30 -> -0.15 | C33: =C32*1.1 -> 3993 | E33: =(A33-A30)/A30*C30+(A33-A31)/A31*C31+(A33-A32)/A32*C32 -> -999.03509 | F33: =E33/SUM(C30:C33) -> -0.071754298
A34: =A30*0.8 -> 4278.224 | B34: =(A34-A30)/A30 -> -0.2 | C34: =C33*1.1 -> 4392.3 | E34: =(A34-A30)/A30*C30+(A34-A31)/A31*C31+(A34-A32)/A32*C32+(A34-A33)/A33*C33 -> -1759.2683 | F34: =E34/SUM(C30:C34) -> -0.096054573
A35: =A30*0.75 -> 4010.835 | B35: =(A35-A30)/A30 -> -0.25 | C35: =C34*1.1 -> 4831.53 | E35: =(A35-A30)/A30*C30+(A35-A31)/A31*C31+(A35-A32)/A32*C32+(A35-A33)/A33*C33+(A35-A34)/A34*C34 -> -2794.0203 | F35: =E35/SUM(C30:C35) -> -0.12070855
A36: =A30*0.7 -> 3743.446 | B36: =(A36-A30)/A30 -> -0.3 | C36: =C35*1.1 -> 5314.683 | E36: =(A36-A30)/A30*C30+(A36-A31)/A31*C31+(A36-A32)/A32*C32+(A36-A33)/A33*C33+(A36-A34)/A34*C34+(A36-A35)/A35*C35 -> -4150.8743 | F36: =E36/SUM(C30:C36) -> -0.14584166
A37: =A30*0.65 -> 3476.057 | B37: =(A37-A30)/A30 -> -0.35 | C37: =C36*1.1 -> 5846.1513 | E37: =(A37-A30)/A30*C30+(A37-A31)/A31*C31+(A37-A32)/A32*C32+(A37-A33)/A33*C33+(A37-A34)/A34*C34+(A37-A35)/A35*C35+(A37-A36)/A36*C36 -> -5887.3485 | F37: =E37/SUM(C30:C37) -> -0.17160447
A38: =A30*0.6 -> 3208.668 | B38: =(A38-A30)/A30 -> -0.4 | C38: =C37*1.1 -> 6430.7664 | E38: =(A38-A30)/A30*C30+(A38-A31)/A31*C31+(A38-A32)/A32*C32+(A38-A33)/A33*C33+(A38-A34)/A34*C34+(A38-A35)/A35*C35+(A38-A36)/A36*C36+(A38-A37)/A37*C37 -> -8073.5266 | F38: =E38/SUM(C30:C38) -> -0.19817962
A39: =A30*0.55 -> 2941.279 | B39: =(A39-A30)/A30 -> -0.45 | C39: =C38*1.1 -> 7073.8431 | E39: =(A39-A30)/A30*C30+(A39-A31)/A31*C31+(A39-A32)/A32*C32+(A39-A33)/A33*C33+(A39-A34)/A34*C34+(A39-A35)/A35*C35+(A39-A36)/A36*C36+(A39-A37)/A37*C37+(A39-A38)/A38*C38 -> -10795.602 | F39: =E39/SUM(C30:C39) -> -0.22579144
C41: =SUM(C30:C39) -> 47812.274 | D41: =SUM(D30:D39) -> 3000

Sheet 中小板
D1: 43940
D2: PE 28.28/34%
D3: PB 3.51/32%
A5: =A6*105% -> 9332.5837 | B5: =(A5-A13)/A13 -> 0.47745544 | C5: =C6*0.9 -> 107.6168
A6: =A7*105% -> 8888.175 | B6: =(A6-A13)/A13 -> 0.40710042 | C6: =C7*0.9 -> 119.57422
A7: =A8*105% -> 8464.9285 | B7: =(A7-A13)/A13 -> 0.34009564 | C7: =C8*0.9 -> 132.86025
A8: =A9*105% -> 8061.8367 | B8: =(A8-A13)/A13 -> 0.27628156 | C8: =C9*0.9 -> 147.6225
A9: =A10*105% -> 7677.9397 | B9: =(A9-A13)/A13 -> 0.21550625 | C9: =C10*0.9 -> 164.025
A10: =A11*105% -> 7312.3235 | B10: =(A10-A13)/A13 -> 0.157625 | C10: =C11*0.9 -> 182.25
A11: =A12*105% -> 6964.1177 | B11: =(A11-A13)/A13 -> 0.1025 | C11: =C12*0.9 -> 202.5
A12: =A13*105% -> 6632.493 | B12: =(A12-A13)/A13 -> 0.05 | C12: =C13*0.9 -> 225
A13: 6316.66 | B13: =(A13-A13)/A13 -> 0 | C13: 250
A14: =A13*0.95 -> 6000.827 | B14: =(A14-A13)/A13 -> -0.05 | C14: =C13*1.1 -> 275
A15: =A13*0.9 -> 5684.994 | B15: =(A15-A13)/A13 -> -0.1 | C15: =C13*1.2 -> 300
A16: =A13*0.85 -> 5369.161 | B16: =(A16-A13)/A13 -> -0.15 | C16: =C13*1.3 -> 325
A17: =A13*0.8 -> 5053.328 | B17: =(A17-A13)/A13 -> -0.2 | C17: =C13*1.4 -> 350
A18: =A13*0.75 -> 4737.495 | B18: =(A18-A13)/A13 -> -0.25 | C18: =C13*1.5 -> 375
A19: =A13*0.7 -> 4421.662 | B19: =(A19-A13)/A13 -> -0.3 | C19: =C13*1.6 -> 400
A20: =A13*0.65 -> 4105.829 | B20: =(A20-A13)/A13 -> -0.35 | C20: =C13*1.7 -> 425
A21: =A13*0.6 -> 3789.996 | B21: =(A21-A13)/A13 -> -0.4 | C21: =C13*1.8 -> 450
A22: =A13*0.55 -> 3474.163 | B22: =(A22-A13)/A13 -> -0.45 | C22: =C13*1.9 -> 475
A23: =A13*0.5 -> 3158.33 | B23: =(A23-A13)/A13 -> -0.5 | C23: =C13*2 -> 500
A24: =A13*0.45 -> 2842.497 | B24: =(A24-A13)/A13 -> -0.55 | C24: =C13*2.1 -> 525
A25: =A13*0.4 -> 2526.664 | B25: =(A25-A13)/A13 -> -0.6 | C25: =C13*2.2 -> 550
A26: =A13*0.35 -> 2210.831 | B26: =(A26-A13)/A13 -> -0.65 | C26: =C13*2.3 -> 575
A30: 6316.66 | B30: =(A30-A30)/A30 -> 0 | C30: 5500 | E30: 0 | F30: 0
A31: =A30*0.95 -> 6000.827 | B31: =(A31-A30)/A30 -> -0.05 | C31: =C30*1.1 -> 6050 | E31: =(A31-A30)/A30*C30 -> -275 | F31: =E31/SUM(C30:C31) -> -0.023809524
A32: =A30*0.9 -> 5684.994 | B32: =(A32-A30)/A30 -> -0.1 | C32: =C31*1.1 -> 6655 | E32: =(A32-A30)/A30*C30+(A32-A31)/A31*C31 -> -868.42105 | F32: =E32/SUM(C30:C32) -> -0.047702337
A33: =A30*0.85 -> 5369.161 | B33: =(A33-A30)/A30 -> -0.15 | C33: =C32*1.1 -> 7320.5 | E33: =(A33-A30)/A30*C30+(A33-A31)/A31*C31+(A33-A32)/A32*C32 -> -1831.5643 | F33: =E33/SUM(C30:C33) -> -0.071754298
A34: =A30*0.8 -> 5053.328 | B34: =(A34-A30)/A30 -> -0.2 | C34: =C33*1.1 -> 8052.55 | E34: =(A34-A30)/A30*C30+(A34-A31)/A31*C31+(A34-A32)/A32*C32+(A34-A33)/A33*C33 -> -3225.3252 | F34: =E34/SUM(C30:C34) -> -0.096054573
A35: =A30*0.75 -> 4737.495 | B35: =(A35-A30)/A30 -> -0.25 | C35: =C34*1.1 -> 8857.805 | E35: =(A35-A30)/A30*C30+(A35-A31)/A31*C31+(A35-A32)/A32*C32+(A35-A33)/A33*C33+(A35-A34)/A34*C34 -> -5122.3705 | F35: =E35/SUM(C30:C35) -> -0.12070855
A36: =A30*0.7 -> 4421.662 | B36: =(A36-A30)/A30 -> -0.3 | C36: =C35*1.1 -> 9743.5855 | E36: =(A36-A30)/A30*C30+(A36-A31)/A31*C31+(A36-A32)/A32*C32+(A36-A33)/A33*C33+(A36-A34)/A34*C34+(A36-A35)/A35*C35 -> -7609.9362 | F36: =E36/SUM(C30:C36) -> -0.14584166
A37: =A30*0.65 -> 4105.829 | B37: =(A37-A30)/A30 -> -0.35 | C37: =C36*1.1 -> 10717.944 | E37: =(A37-A30)/A30*C30+(A37-A31)/A31*C31+(A37-A32)/A32*C32+(A37-A33)/A33*C33+(A37-A34)/A34*C34+(A37-A35)/A35*C35+(A37-A36)/A36*C36 -> -10793.472 | F37: =E37/SUM(C30:C37) -> -0.17160447
A38: =A30*0.6 -> 3789.996 | B38: =(A38-A30)/A30 -> -0.4 | C38: =C37*1.1 -> 11789.738 | E38: =(A38-A30)/A30*C30+(A38-A31)/A31*C31+(A38-A32)/A32*C32+(A38-A33)/A33*C33+(A38-A34)/A34*C34+(A38-A35)/A35*C35+(A38-A36)/A36*C36+(A38-A37)/A37*C37 -> -14801.465 | F38: =E38/SUM(C30:C38) -> -0.19817962
A39: =A30*0.55 -> 3474.163 | B39: =(A39-A30)/A30 -> -0.45 | C39: =C38*1.1 -> 12968.712 | E39: =(A39-A30)/A30*C30+(A39-A31)/A31*C31+(A39-A32)/A32*C32+(A39-A33)/A33*C33+(A39-A34)/A34*C34+(A39-A35)/A35*C35+(A39-A36)/A36*C36+(A39-A37)/A37*C37+(A39-A38)/A38*C38 -> -19791.937 | F39: =E39/SUM(C30:C39) -> -0.22579144
C41: =SUM(C30:C39) -> 87655.835 | D41: =SUM(D30:D39) -> 0

Sheet 银行
D1: 43940
D2: PE 5.89/25.64%
D3: PB 0.73/1.03%
A5: =A6*105% -> 8961.2166 | B5: =(A5-A13)/A13 -> 0.47745544 | C5: =C6*0.9 -> 107.6168
A6: =A7*105% -> 8534.492 | B6: =(A6-A13)/A13 -> 0.40710042 | C6: =C7*0.9 -> 119.57422
A7: =A8*105% -> 8128.0876 | B7: =(A7-A13)/A13 -> 0.34009564 | C7: =C8*0.9 -> 132.86025
A8: =A9*105% -> 7741.0358 | B8: =(A8-A13)/A13 -> 0.27628156 | C8: =C9*0.9 -> 147.6225
A9: =A10*105% -> 7372.415 | B9: =(A9-A13)/A13 -> 0.21550625 | C9: =C10*0.9 -> 164.025
A10: =A11*105% -> 7021.3477 | B10: =(A10-A13)/A13 -> 0.157625 | C10: =C11*0.9 -> 182.25
A11: =A12*105% -> 6686.9978 | B11: =(A11-A13)/A13 -> 0.1025 | C11: =C12*0.9 -> 202.5
A12: =A13*105% -> 6368.5693 | B12: =(A12-A13)/A13 -> 0.05 | C12: =C13*0.9 -> 225
A13: 6065.3041 | B13: =(A13-A13)/A13 -> 0 | C13: 250
A14: =A13*0.95 -> 5762.0389 | B14: =(A14-A13)/A13 -> -0.05 | C14: =C13*1.1 -> 275
A15: =A13*0.9 -> 5458.7737 | B15: =(A15-A13)/A13 -> -0.1 | C15: =C13*1.2 -> 300
A16: =A13*0.85 -> 5155.5085 | B16: =(A16-A13)/A13 -> -0.15 | C16: =C13*1.3 -> 325
A17: =A13*0.8 -> 4852.2433 | B17: =(A17-A13)/A13 -> -0.2 | C17: =C13*1.4 -> 350
A18: =A13*0.75 -> 4548.9781 | B18: =(A18-A13)/A13 -> -0.25 | C18: =C13*1.5 -> 375
A19: =A13*0.7 -> 4245.7129 | B19: =(A19-A13)/A13 -> -0.3 | C19: =C13*1.6 -> 400
A20: =A13*0.65 -> 3942.4477 | B20: =(A20-A13)/A13 -> -0.35 | C20: =C13*1.7 -> 425
A21: =A13*0.6 -> 3639.1825 | B21: =(A21-A13)/A13 -> -0.4 | C21: =C13*1.8 -> 450
A22: =A13*0.55 -> 3335.9173 | B22: =(A22-A13)/A13 -> -0.45 | C22: =C13*1.9 -> 475
A23: =A13*0.5 -> 3032.6521 | B23: =(A23-A13)/A13 -> -0.5 | C23: =C13*2 -> 500
A24: =A13*0.45 -> 2729.3868 | B24: =(A24-A13)/A13 -> -0.55 | C24: =C13*2.1 -> 525
A25: =A13*0.4 -> 2426.1216 | B25: =(A25-A13)/A13 -> -0.6 | C25: =C13*2.2 -> 550
A26: =A13*0.35 -> 2122.8564 | B26: =(A26-A13)/A13 -> -0.65 | C26: =C13*2.3 -> 575
A30: 6065.3041 | B30: =(A30-A30)/A30 -> 0 | C30: 4089.7624 | D30: =C30 -> 4089.7624 | E30: 0 | F30: 0
A31: =A30*0.95 -> 5762.0389 | B31: =(A31-A30)/A30 -> -0.05 | C31: =C30*1.1 -> 4498.7386 | E31: =(A31-A30)/A30*C30 -> -204.48812 | F31: =E31/SUM(C30:C31) -> -0.023809524
A32: =A30*0.9 -> 5458.7737 | B32: =(A32-A30)/A30 -> -0.1 | C32: =C30*1.2 -> 4907.7149 | E32: =(A32-A30)/A30*C30+(A32-A31)/A31*C31 -> -645.75196 | F32: =E32/SUM(C30:C32) -> -0.04784689
A33: =A30*0.85 -> 5155.5085 | B33: =(A33-A30)/A30 -> -0.15 | C33: =C30*1.3 -> 5316.6911 | E33: =(A33-A30)/A30*C30+(A33-A31)/A31*C31+(A33-A32)/A32*C32 -> -1359.6666 | F33: =E33/SUM(C30:C33) -> -0.072273074
A34: =A30*0.8 -> 4852.2433 | B34: =(A34-A30)/A30 -> -0.2 | C34: =C30*1.4 -> 5725.6674 | E34: =(A34-A30)/A30*C30+(A34-A31)/A31*C31+(A34-A32)/A32*C32+(A34-A33)/A33*C33 -> -2386.3278 | F34: =E34/SUM(C30:C34) -> -0.097248022
A35: =A30*0.75 -> 4548.9781 | B35: =(A35-A30)/A30 -> -0.25 | C35: =C30*1.5 -> 6134.6436 | E35: =(A35-A30)/A30*C30+(A35-A31)/A31*C31+(A35-A32)/A32*C32+(A35-A33)/A33*C33+(A35-A34)/A34*C34 -> -3770.8432 | F35: =E35/SUM(C30:C35) -> -0.12293602
A36: =A30*0.7 -> 4245.7129 | B36: =(A36-A30)/A30 -> -0.3 | C36: =C30*1.6 -> 6543.6198 | E36: =(A36-A30)/A30*C30+(A36-A31)/A31*C31+(A36-A32)/A32*C32+(A36-A33)/A33*C33+(A36-A34)/A34*C34+(A36-A35)/A35*C35 -> -5564.3349 | F36: =E36/SUM(C30:C36) -> -0.14951122
A37: =A30*0.65 -> 3942.4477 | B37: =(A37-A30)/A30 -> -0.35 | C37: =C30*1.7 -> 6952.5961 | E37: =(A37-A30)/A30*C30+(A37-A31)/A31*C31+(A37-A32)/A32*C32+(A37-A33)/A33*C33+(A37-A34)/A34*C34+(A37-A35)/A35*C35+(A37-A36)/A36*C36 -> -7825.228 | F37: =E37/SUM(C30:C37) -> -0.17716387
A38: =A30*0.6 -> 3639.1825 | B38: =(A38-A30)/A30 -> -0.4 | C38: =C30*1.8 -> 7361.5723 | E38: =(A38-A30)/A30*C30+(A38-A31)/A31*C31+(A38-A32)/A32*C32+(A38-A33)/A33*C33+(A38-A34)/A34*C34+(A38-A35)/A35*C35+(A38-A36)/A36*C36+(A38-A37)/A37*C37 -> -10620.936 | F38: =E38/SUM(C30:C38) -> -0.20610768
A39: =A30*0.55 -> 3335.9173 | B39: =(A39-A30)/A30 -> -0.45 | C39: =C30*1.9 -> 7770.5486 | E39: =(A39-A30)/A30*C30+(A39-A31)/A31*C31+(A39-A32)/A32*C32+(A39-A33)/A33*C33+(A39-A34)/A34*C34+(A39-A35)/A35*C35+(A39-A36)/A36*C36+(A39-A37)/A37*C37+(A39-A38)/A38*C38 -> -14030.109 | F39: =E39/SUM(C30:C39) -> -0.23658922
C41: =SUM(C30:C39) -> 59301.555 | D41: =SUM(D30:D39) -> 4089.7624

Sheet 证券
D1: 43940
D2: PE 26.14/57.03%
D3: PB 1.69/32.21%
A5: =A6*105% -> 1069.5595 | B5: =(A5-A13)/A13 -> 0.47745544 | C5: =C6*0.9 -> 107.6168
A6: =A7*105% -> 1018.6281 | B6: =(A6-A13)/A13 -> 0.40710042 | C6: =C7*0.9 -> 119.57422
A7: =A8*105% -> 970.12204 | B7: =(A7-A13)/A13 -> 0.34009564 | C7: =C8*0.9 -> 132.86025
A8: =A9*105% -> 923.92575 | B8: =(A8-A13)/A13 -> 0.27628156 | C8: =C9*0.9 -> 147.6225
A9: =A10*105% -> 879.92928 | B9: =(A9-A13)/A13 -> 0.21550625 | C9: =C10*0.9 -> 164.025
A10: =A11*105% -> 838.02789 | B10: =(A10-A13)/A13 -> 0.157625 | C10: =C11*0.9 -> 182.25
A11: =A12*105% -> 798.1218 | B11: =(A11-A13)/A13 -> 0.1025 | C11: =C12*0.9 -> 202.5
A12: =A13*105% -> 760.116 | B12: =(A12-A13)/A13 -> 0.05 | C12: =C13*0.9 -> 225
A13: 723.92 | B13: =(A13-A13)/A13 -> 0 | C13: 250
A14: =A13*0.95 -> 687.724 | B14: =(A14-A13)/A13 -> -0.05 | C14: =C13*1.1 -> 275
A15: =A13*0.9 -> 651.528 | B15: =(A15-A13)/A13 -> -0.1 | C15: =C13*1.2 -> 300
A16: =A13*0.85 -> 615.332 | B16: =(A16-A13)/A13 -> -0.15 | C16: =C13*1.3 -> 325
A17: =A13*0.8 -> 579.136 | B17: =(A17-A13)/A13 -> -0.2 | C17: =C13*1.4 -> 350
A18: =A13*0.75 -> 542.94 | B18: =(A18-A13)/A13 -> -0.25 | C18: =C13*1.5 -> 375
A19: =A13*0.7 -> 506.744 | B19: =(A19-A13)/A13 -> -0.3 | C19: =C13*1.6 -> 400
A20: =A13*0.65 -> 470.548 | B20: =(A20-A13)/A13 -> -0.35 | C20: =C13*1.7 -> 425
A21: =A13*0.6 -> 434.352 | B21: =(A21-A13)/A13 -> -0.4 | C21: =C13*1.8 -> 450
A22: =A13*0.55 -> 398.156 | B22: =(A22-A13)/A13 -> -0.45 | C22: =C13*1.9 -> 475
A23: =A13*0.5 -> 361.96 | B23: =(A23-A13)/A13 -> -0.5 | C23: =C13*2 -> 500
A24: =A13*0.45 -> 325.764 | B24: =(A24-A13)/A13 -> -0.55 | C24: =C13*2.1 -> 525
A25: =A13*0.4 -> 289.568 | B25: =(A25-A13)/A13 -> -0.6 | C25: =C13*2.2 -> 550
A26: =A13*0.35 -> 253.372 | B26: =(A26-A13)/A13 -> -0.65 | C26: =C13*2.3 -> 575
A30: 747.45 | B30: =(A30-A30)/A30 -> 0 | C30: 1000 | E30: 0 | F30: 0
A31: =A30*0.95 -> 710.0775 | B31: =(A31-A30)/A30 -> -0.05 | C31: =C30*1.1 -> 1100 | E31: =(A31-A30)/A30*C30 -> -50 | F31: =E31/SUM(C30:C31) -> -0.023809524
A32: =A30*0.9 -> 672.705 | B32: =(A32-A30)/A30 -> -0.1 | C32: =C31*1.1 -> 1210 | E32: =(A32-A30)/A30*C30+(A32-A31)/A31*C31 -> -157.89474 | F32: =E32/SUM(C30:C32) -> -0.047702337
A33: =A30*0.85 -> 635.3325 | B33: =(A33-A30)/A30 -> -0.15 | C33: =C32*1.1 -> 1331 | E33: =(A33-A30)/A30*C30+(A33-A31)/A31*C31+(A33-A32)/A32*C32 -> -333.0117 | F33: =E33/SUM(C30:C33) -> -0.071754298
A34: =A30*0.8 -> 597.96 | B34: =(A34-A30)/A30 -> -0.2 | C34: =C33*1.1 -> 1464.1 | E34: =(A34-A30)/A30*C30+(A34-A31)/A31*C31+(A34-A32)/A32*C32+(A34-A33)/A33*C33 -> -586.42277 | F34: =E34/SUM(C30:C34) -> -0.096054573
A35: =A30*0.75 -> 560.5875 | B35: =(A35-A30)/A30 -> -0.25 | C35: =C34*1.1 -> 1610.51 | E35: =(A35-A30)/A30*C30+(A35-A31)/A31*C31+(A35-A32)/A32*C32+(A35-A33)/A33*C33+(A35-A34)/A34*C34 -> -931.3401 | F35: =E35/SUM(C30:C35) -> -0.12070855
A36: =A30*0.7 -> 523.215 | B36: =(A36-A30)/A30 -> -0.3 | C36: =C35*1.1 -> 1771.561 | E36: =(A36-A30)/A30*C30+(A36-A31)/A31*C31+(A36-A32)/A32*C32+(A36-A33)/A33*C33+(A36-A34)/A34*C34+(A36-A35)/A35*C35 -> -1383.6248 | F36: =E36/SUM(C30:C36) -> -0.14584166
A37: =A30*0.65 -> 485.8425 | B37: =(A37-A30)/A30 -> -0.35 | C37: =C36*1.1 -> 1948.7171 | E37: =(A37-A30)/A30*C30+(A37-A31)/A31*C31+(A37-A32)/A32*C32+(A37-A33)/A33*C33+(A37-A34)/A34*C34+(A37-A35)/A35*C35+(A37-A36)/A36*C36 -> -1962.4495 | F37: =E37/SUM(C30:C37) -> -0.17160447
A38: =A30*0.6 -> 448.47 | B38: =(A38-A30)/A30 -> -0.4 | C38: =C37*1.1 -> 2143.5888 | E38: =(A38-A30)/A30*C30+(A38-A31)/A31*C31+(A38-A32)/A32*C32+(A38-A33)/A33*C33+(A38-A34)/A34*C34+(A38-A35)/A35*C35+(A38-A36)/A36*C36+(A38-A37)/A37*C37 -> -2691.1755 | F38: =E38/SUM(C30:C38) -> -0.19817962
A39: =A30*0.55 -> 411.0975 | B39: =(A39-A30)/A30 -> -0.45 | C39: =C38*1.1 -> 2357.9477 | E39: =(A39-A30)/A30*C30+(A39-A31)/A31*C31+(A39-A32)/A32*C32+(A39-A33)/A33*C33+(A39-A34)/A34*C34+(A39-A35)/A35*C35+(A39-A36)/A36*C36+(A39-A37)/A37*C37+(A39-A38)/A38*C38 -> -3598.534 | F39: =E39/SUM(C30:C39) -> -0.22579144
C41: =SUM(C30:C39) -> 15937.425 | D41: =SUM(D30:D39) -> 0

Sheet 军工
D1: 43940
D2: PE 56.7/12.41%
D3: PB 2.59/23.39%
A5: =A6*105% -> 1627.3137 | B5: =(A5-A13)/A13 -> 0.47745544 | C5: =C6*0.9 -> 107.6168
A6: =A7*105% -> 1549.8226 | B6: =(A6-A13)/A13 -> 0.40710042 | C6: =C7*0.9 -> 119.57422
A7: =A8*105% -> 1476.0215 | B7: =(A7-A13)/A13 -> 0.34009564 | C7: =C8*0.9 -> 132.86025
A8: =A9*105% -> 1405.7348 | B8: =(A8-A13)/A13 -> 0.27628156 | C8: =C9*0.9 -> 147.6225
A9: =A10*105% -> 1338.795 | B9: =(A9-A13)/A13 -> 0.21550625 | C9: =C10*0.9 -> 164.025
A10: =A11*105% -> 1275.0429 | B10: =(A10-A13)/A13 -> 0.157625 | C10: =C11*0.9 -> 182.25
A11: =A12*105% -> 1214.3266 | B11: =(A11-A13)/A13 -> 0.1025 | C11: =C12*0.9 -> 202.5
A12: =A13*105% -> 1156.5015 | B12: =(A12-A13)/A13 -> 0.05 | C12: =C13*0.9 -> 225
A13: 1101.43 | B13: =(A13-A13)/A13 -> 0 | C13: 250
A14: =A13*0.95 -> 1046.3585 | B14: =(A14-A13)/A13 -> -0.05 | C14: =C13*1.1 -> 275
A15: =A13*0.9 -> 991.287 | B15: =(A15-A13)/A13 -> -0.1 | C15: =C13*1.2 -> 300
A16: =A13*0.85 -> 936.2155 | B16: =(A16-A13)/A13 -> -0.15 | C16: =C13*1.3 -> 325
A17: =A13*0.8 -> 881.144 | B17: =(A17-A13)/A13 -> -0.2 | C17: =C13*1.4 -> 350
A18: =A13*0.75 -> 826.0725 | B18: =(A18-A13)/A13 -> -0.25 | C18: =C13*1.5 -> 375
A19: =A13*0.7 -> 771.001 | B19: =(A19-A13)/A13 -> -0.3 | C19: =C13*1.6 -> 400
A20: =A13*0.65 -> 715.9295 | B20: =(A20-A13)/A13 -> -0.35 | C20: =C13*1.7 -> 425
A21: =A13*0.6 -> 660.858 | B21: =(A21-A13)/A13 -> -0.4 | C21: =C13*1.8 -> 450
A22: =A13*0.55 -> 605.7865 | B22: =(A22-A13)/A13 -> -0.45 | C22: =C13*1.9 -> 475
A23: =A13*0.5 -> 550.715 | B23: =(A23-A13)/A13 -> -0.5 | C23: =C13*2 -> 500
A24: =A13*0.45 -> 495.6435 | B24: =(A24-A13)/A13 -> -0.55 | C24: =C13*2.1 -> 525
A25: =A13*0.4 -> 440.572 | B25: =(A25-A13)/A13 -> -0.6 | C25: =C13*2.2 -> 550
A26: =A13*0.35 -> 385.5005 | B26: =(A26-A13)/A13 -> -0.65 | C26: =C13*2.3 -> 575
A30: 1101.43 | B30: =(A30-A30)/A30 -> 0 | C30: 1600 | D30: =C30 -> 1600 | E30: 0 | F30: 0
A31: =A30*0.95 -> 1046.3585 | B31: =(A31-A30)/A30 -> -0.05 | C31: =C30*1.1 -> 1760 | E31: =(A31-A30)/A30*C30 -> -80 | F31: =E31/SUM(C30:C31) -> -0.023809524
A32: =A30*0.9 -> 991.287 | B32: =(A32-A30)/A30 -> -0.1 | C32: =C30*1.2 -> 1920 | E32: =(A32-A30)/A30*C30+(A32-A31)/A31*C31 -> -252.63158 | F32: =E32/SUM(C30:C32) -> -0.04784689
A33: =A30*0.85 -> 936.2155 | B33: =(A33-A30)/A30 -> -0.15 | C33: =C30*1.3 -> 2080 | E33: =(A33-A30)/A30*C30+(A33-A31)/A31*C31+(A33-A32)/A32*C32 -> -531.92982 | F33: =E33/SUM(C30:C33) -> -0.072273074
A34: =A30*0.8 -> 881.144 | B34: =(A34-A30)/A30 -> -0.2 | C34: =C30*1.4 -> 2240 | E34: =(A34-A30)/A30*C30+(A34-A31)/A31*C31+(A34-A32)/A32*C32+(A34-A33)/A33*C33 -> -933.58101 | F34: =E34/SUM(C30:C34) -> -0.097248022
A35: =A30*0.75 -> 826.0725 | B35: =(A35-A30)/A30 -> -0.25 | C35: =C30*1.5 -> 2400 | E35: =(A35-A30)/A30*C30+(A35-A31)/A31*C31+(A35-A32)/A32*C32+(A35-A33)/A33*C33+(A35-A34)/A34*C34 -> -1475.2322 | F35: =E35/SUM(C30:C35) -> -0.12293602
A36: =A30*0.7 -> 771.001 | B36: =(A36-A30)/A30 -> -0.3 | C36: =C30*1.6 -> 2560 | E36: =(A36-A30)/A30*C30+(A36-A31)/A31*C31+(A36-A32)/A32*C32+(A36-A33)/A33*C33+(A36-A34)/A34*C34+(A36-A35)/A35*C35 -> -2176.8834 | F36: =E36/SUM(C30:C36) -> -0.14951122
A37: =A30*0.65 -> 715.9295 | B37: =(A37-A30)/A30 -> -0.35 | C37: =C30*1.7 -> 2720 | E37: =(A37-A30)/A30*C30+(A37-A31)/A31*C31+(A37-A32)/A32*C32+(A37-A33)/A33*C33+(A37-A34)/A34*C34+(A37-A35)/A35*C35+(A37-A36)/A36*C36 -> -3061.3917 | F37: =E37/SUM(C30:C37) -> -0.17716387
A38: =A30*0.6 -> 660.858 | B38: =(A38-A30)/A30 -> -0.4 | C38: =C30*1.8 -> 2880 | E38: =(A38-A30)/A30*C30+(A38-A31)/A31*C31+(A38-A32)/A32*C32+(A38-A33)/A33*C33+(A38-A34)/A34*C34+(A38-A35)/A35*C35+(A38-A36)/A36*C36+(A38-A37)/A37*C37 -> -4155.1308 | F38: =E38/SUM(C30:C38) -> -0.20610768
A39: =A30*0.55 -> 605.7865 | B39: =(A39-A30)/A30 -> -0.45 | C39: =C30*1.9 -> 3040 | E39: =(A39-A30)/A30*C30+(A39-A31)/A31*C31+(A39-A32)/A32*C32+(A39-A33)/A33*C33+(A39-A34)/A34*C34+(A39-A35)/A35*C35+(A39-A36)/A36*C36+(A39-A37)/A37*C37+(A39-A38)/A38*C38 -> -5488.8699 | F39: =E39/SUM(C30:C39) -> -0.23658922
C41: =SUM(C30:C39) -> 23200 | D41: =SUM(D30:D39) -> 1600

Sheet 地产等权
D1: 43940
D2: PE 7.06/1.4%
D3: PB 1.36/2.71%
A5: =A6*105% -> 10050.272 | B5: =(A5-A13)/A13 -> 0.47745544 | C5: =C6*0.9 -> 107.6168
A6: =A7*105% -> 9571.6881 | B6: =(A6-A13)/A13 -> 0.40710042 | C6: =C7*0.9 -> 119.57422
A7: =A8*105% -> 9115.8934 | B7: =(A7-A13)/A13 -> 0.34009564 | C7: =C8*0.9 -> 132.86025
A8: =A9*105% -> 8681.8032 | B8: =(A8-A13)/A13 -> 0.27628156 | C8: =C9*0.9 -> 147.6225
A9: =A10*105% -> 8268.384 | B9: =(A9-A13)/A13 -> 0.21550625 | C9: =C10*0.9 -> 164.025
A10: =A11*105% -> 7874.6515 | B10: =(A10-A13)/A13 -> 0.157625 | C10: =C11*0.9 -> 182.25
A11: =A12*105% -> 7499.6681 | B11: =(A11-A13)/A13 -> 0.1025 | C11: =C12*0.9 -> 202.5
A12: =A13*105% -> 7142.541 | B12: =(A12-A13)/A13 -> 0.05 | C12: =C13*0.9 -> 225
A13: 6802.42 | B13: =(A13-A13)/A13 -> 0 | C13: 250
A14: =A13*0.95 -> 6462.299 | B14: =(A14-A13)/A13 -> -0.05 | C14: =C13*1.1 -> 275
A15: =A13*0.9 -> 6122.178 | B15: =(A15-A13)/A13 -> -0.1 | C15: =C13*1.2 -> 300
A16: =A13*0.85 -> 5782.057 | B16: =(A16-A13)/A13 -> -0.15 | C16: =C13*1.3 -> 325
A17: =A13*0.8 -> 5441.936 | B17: =(A17-A13)/A13 -> -0.2 | C17: =C13*1.4 -> 350
A18: =A13*0.75 -> 5101.815 | B18: =(A18-A13)/A13 -> -0.25 | C18: =C13*1.5 -> 375
A19: =A13*0.7 -> 4761.694 | B19: =(A19-A13)/A13 -> -0.3 | C19: =C13*1.6 -> 400
A20: =A13*0.65 -> 4421.573 | B20: =(A20-A13)/A13 -> -0.35 | C20: =C13*1.7 -> 425
A21: =A13*0.6 -> 4081.452 | B21: =(A21-A13)/A13 -> -0.4 | C21: =C13*1.8 -> 450
A22: =A13*0.55 -> 3741.331 | B22: =(A22-A13)/A13 -> -0.45 | C22: =C13*1.9 -> 475
A23: =A13*0.5 -> 3401.21 | B23: =(A23-A13)/A13 -> -0.5 | C23: =C13*2 -> 500
A24: =A13*0.45 -> 3061.089 | B24: =(A24-A13)/A13 -> -0.55 | C24: =C13*2.1 -> 525
A25: =A13*0.4 -> 2720.968 | B25: =(A25-A13)/A13 -> -0.6 | C25: =C13*2.2 -> 550
A26: =A13*0.35 -> 2380.847 | B26: =(A26-A13)/A13 -> -0.65 | C26: =C13*2.3 -> 575
A30: 6802.42 | B30: =(A30-A30)/A30 -> 0 | C30: 2400 | D30: =C30 -> 2400 | E30: 0 | F30: 0
A31: =A30*0.95 -> 6462.299 | B31: =(A31-A30)/A30 -> -0.05 | C31: =C30*1.1 -> 2640 | D31: =D30*1.1 -> 2640 | E31: =(A31-A30)/A30*C30 -> -120 | F31: =E31/SUM(C30:C31) -> -0.023809524
A32: =A30*0.9 -> 6122.178 | B32: =(A32-A30)/A30 -> -0.1 | C32: =C31*1.1 -> 2904 | E32: =(A32-A30)/A30*C30+(A32-A31)/A31*C31 -> -378.94737 | F32: =E32/SUM(C30:C32) -> -0.047702337
A33: =A30*0.85 -> 5782.057 | B33: =(A33-A30)/A30 -> -0.15 | C33: =C32*1.1 -> 3194.4 | E33: =(A33-A30)/A30*C30+(A33-A31)/A31*C31+(A33-A32)/A32*C32 -> -799.22807 | F33: =E33/SUM(C30:C33) -> -0.071754298
A34: =A30*0.8 -> 5441.936 | B34: =(A34-A30)/A30 -> -0.2 | C34: =C33*1.1 -> 3513.84 | E34: =(A34-A30)/A30*C30+(A34-A31)/A31*C31+(A34-A32)/A32*C32+(A34-A33)/A33*C33 -> -1407.4147 | F34: =E34/SUM(C30:C34) -> -0.096054573
A35: =A30*0.75 -> 5101.815 | B35: =(A35-A30)/A30 -> -0.25 | C35: =C34*1.1 -> 3865.224 | E35: =(A35-A30)/A30*C30+(A35-A31)/A31*C31+(A35-A32)/A32*C32+(A35-A33)/A33*C33+(A35-A34)/A34*C34 -> -2235.2162 | F35: =E35/SUM(C30:C35) -> -0.12070855
A36: =A30*0.7 -> 4761.694 | B36: =(A36-A30)/A30 -> -0.3 | C36: =C35*1.1 -> 4251.7464 | E36: =(A36-A30)/A30*C30+(A36-A31)/A31*C31+(A36-A32)/A32*C32+(A36-A33)/A33*C33+(A36-A34)/A34*C34+(A36-A35)/A35*C35 -> -3320.6994 | F36: =E36/SUM(C30:C36) -> -0.14584166
A37: =A30*0.65 -> 4421.573 | B37: =(A37-A30)/A30 -> -0.35 | C37: =C36*1.1 -> 4676.921 | E37: =(A37-A30)/A30*C30+(A37-A31)/A31*C31+(A37-A32)/A32*C32+(A37-A33)/A33*C33+(A37-A34)/A34*C34+(A37-A35)/A35*C35+(A37-A36)/A36*C36 -> -4709.8788 | F37: =E37/SUM(C30:C37) -> -0.17160447
A38: =A30*0.6 -> 4081.452 | B38: =(A38-A30)/A30 -> -0.4 | C38: =C37*1.1 -> 5144.6131 | E38: =(A38-A30)/A30*C30+(A38-A31)/A31*C31+(A38-A32)/A32*C32+(A38-A33)/A33*C33+(A38-A34)/A34*C34+(A38-A35)/A35*C35+(A38-A36)/A36*C36+(A38-A37)/A37*C37 -> -6458.8213 | F38: =E38/SUM(C30:C38) -> -0.19817962
A39: =A30*0.55 -> 3741.331 | B39: =(A39-A30)/A30 -> -0.45 | C39: =C38*1.1 -> 5659.0745 | E39: =(A39-A30)/A30*C30+(A39-A31)/A31*C31+(A39-A32)/A32*C32+(A39-A33)/A33*C33+(A39-A34)/A34*C34+(A39-A35)/A35*C35+(A39-A36)/A36*C36+(A39-A37)/A37*C37+(A39-A38)/A38*C38 -> -8636.4816 | F39: =E39/SUM(C30:C39) -> -0.22579144
C41: =SUM(C30:C39) -> 38249.819 | D41: =SUM(D30:D39) -> 5040

Sheet 基建
D1: 43940
D2: PE 7.78/2.05%
D3: PB 0.77/1.56%
A5: =A6*105% -> 5282.0066 | B5: =(A5-A13)/A13 -> 0.47745544 | C5: =C6*0.9 -> 107.6168
A6: =A7*105% -> 5030.4825 | B6: =(A6-A13)/A13 -> 0.40710042 | C6: =C7*0.9 -> 119.57422
A7: =A8*105% -> 4790.9357 | B7: =(A7-A13)/A13 -> 0.34009564 | C7: =C8*0.9 -> 132.86025
A8: =A9*105% -> 4562.7959 | B8: =(A8-A13)/A13 -> 0.27628156 | C8: =C9*0.9 -> 147.6225
A9: =A10*105% -> 4345.5199 | B9: =(A9-A13)/A13 -> 0.21550625 | C9: =C10*0.9 -> 164.025
A10: =A11*105% -> 4138.5904 | B10: =(A10-A13)/A13 -> 0.157625 | C10: =C11*0.9 -> 182.25
A11: =A12*105% -> 3941.5147 | B11: =(A11-A13)/A13 -> 0.1025 | C11: =C12*0.9 -> 202.5
A12: =A13*105% -> 3753.8235 | B12: =(A12-A13)/A13 -> 0.05 | C12: =C13*0.9 -> 225
A13: 3575.07 | B13: =(A13-A13)/A13 -> 0 | C13: 250
A14: =A13*0.95 -> 3396.3165 | B14: =(A14-A13)/A13 -> -0.05 | C14: =C13*1.1 -> 275
A15: =A13*0.9 -> 3217.563 | B15: =(A15-A13)/A13 -> -0.1 | C15: =C13*1.2 -> 300
A16: =A13*0.85 -> 3038.8095 | B16: =(A16-A13)/A13 -> -0.15 | C16: =C13*1.3 -> 325
A17: =A13*0.8 -> 2860.056 | B17: =(A17-A13)/A13 -> -0.2 | C17: =C13*1.4 -> 350
A18: =A13*0.75 -> 2681.3025 | B18: =(A18-A13)/A13 -> -0.25 | C18: =C13*1.5 -> 375
A19: =A13*0.7 -> 2502.549 | B19: =(A19-A13)/A13 -> -0.3 | C19: =C13*1.6 -> 400
A20: =A13*0.65 -> 2323.7955 | B20: =(A20-A13)/A13 -> -0.35 | C20: =C13*1.7 -> 425
A21: =A13*0.6 -> 2145.042 | B21: =(A21-A13)/A13 -> -0.4 | C21: =C13*1.8 -> 450
A22: =A13*0.55 -> 1966.2885 | B22: =(A22-A13)/A13 -> -0.45 | C22: =C13*1.9 -> 475
A23: =A13*0.5 -> 1787.535 | B23: =(A23-A13)/A13 -> -0.5 | C23: =C13*2 -> 500
A24: =A13*0.45 -> 1608.7815 | B24: =(A24-A13)/A13 -> -0.55 | C24: =C13*2.1 -> 525
A25: =A13*0.4 -> 1430.028 | B25: =(A25-A13)/A13 -> -0.6 | C25: =C13*2.2 -> 550
A26: =A13*0.35 -> 1251.2745 | B26: =(A26-A13)/A13 -> -0.65 | C26: =C13*2.3 -> 575
A30: 3575.07 | B30: =(A30-A30)/A30 -> 0 | C30: 1120.53 | D30: =C30 -> 1120.53 | E30: 0 | F30: 0
A31: =A30*0.95 -> 3396.3165 | B31: =(A31-A30)/A30 -> -0.05 | C31: =C30*1.1 -> 1232.583 | D31: =D30*1.1 -> 1232.583 | E31: =(A31-A30)/A30*C30 -> -56.0265 | F31: =E31/SUM(C30:C31) -> -0.023809524
A32: =A30*0.9 -> 3217.563 | B32: =(A32-A30)/A30 -> -0.1 | C32: =C31*1.1 -> 1355.8413 | E32: =(A32-A30)/A30*C30+(A32-A31)/A31*C31 -> -176.92579 | F32: =E32/SUM(C30:C32) -> -0.047702337
A33: =A30*0.85 -> 3038.8095 | B33: =(A33-A30)/A30 -> -0.15 | C33: =C32*1.1 -> 1491.4254 | E33: =(A33-A30)/A30*C30+(A33-A31)/A31*C31+(A33-A32)/A32*C32 -> -373.1496 | F33: =E33/SUM(C30:C33) -> -0.071754298
A34: =A30*0.8 -> 2860.056 | B34: =(A34-A30)/A30 -> -0.2 | C34: =C33*1.1 -> 1640.568 | E34: =(A34-A30)/A30*C30+(A34-A31)/A31*C31+(A34-A32)/A32*C32+(A34-A33)/A33*C33 -> -657.10431 | F34: =E34/SUM(C30:C34) -> -0.096054573
A35: =A30*0.75 -> 2681.3025 | B35: =(A35-A30)/A30 -> -0.25 | C35: =C34*1.1 -> 1804.6248 | E35: =(A35-A30)/A30*C30+(A35-A31)/A31*C31+(A35-A32)/A32*C32+(A35-A33)/A33*C33+(A35-A34)/A34*C34 -> -1043.5945 | F35: =E35/SUM(C30:C35) -> -0.12070855
A36: =A30*0.7 -> 2502.549 | B36: =(A36-A30)/A30 -> -0.3 | C36: =C35*1.1 -> 1985.0872 | E36: =(A36-A30)/A30*C30+(A36-A31)/A31*C31+(A36-A32)/A32*C32+(A36-A33)/A33*C33+(A36-A34)/A34*C34+(A36-A35)/A35*C35 -> -1550.3931 | F36: =E36/SUM(C30:C36) -> -0.14584166
A37: =A30*0.65 -> 2323.7955 | B37: =(A37-A30)/A30 -> -0.35 | C37: =C36*1.1 -> 2183.596 | E37: =(A37-A30)/A30*C30+(A37-A31)/A31*C31+(A37-A32)/A32*C32+(A37-A33)/A33*C33+(A37-A34)/A34*C34+(A37-A35)/A35*C35+(A37-A36)/A36*C36 -> -2198.9835 | F37: =E37/SUM(C30:C37) -> -0.17160447
A38: =A30*0.6 -> 2145.042 | B38: =(A38-A30)/A30 -> -0.4 | C38: =C37*1.1 -> 2401.9556 | E38: =(A38-A30)/A30*C30+(A38-A31)/A31*C31+(A38-A32)/A32*C32+(A38-A33)/A33*C33+(A38-A34)/A34*C34+(A38-A35)/A35*C35+(A38-A36)/A36*C36+(A38-A37)/A37*C37 -> -3015.5429 | F38: =E38/SUM(C30:C38) -> -0.19817962
A39: =A30*0.55 -> 1966.2885 | B39: =(A39-A30)/A30 -> -0.45 | C39: =C38*1.1 -> 2642.1511 | E39: =(A39-A30)/A30*C30+(A39-A31)/A31*C31+(A39-A32)/A32*C32+(A39-A33)/A33*C33+(A39-A34)/A34*C34+(A39-A35)/A35*C35+(A39-A36)/A36*C36+(A39-A37)/A37*C37+(A39-A38)/A38*C38 -> -4032.2653 | F39: =E39/SUM(C30:C39) -> -0.22579144
C41: =SUM(C30:C39) -> 17858.362 | D41: =SUM(D30:D39) -> 2353.113

Sheet 养老
D1: 43940
D2: PE 18.56/5.86%
D3: PB 2.98/47.45%
A5: =A6*105% -> 11354.496 | B5: =(A5-A13)/A13 -> 0.47745544 | C5: =C6*0.9 -> 107.6168
A6: =A7*105% -> 10813.806 | B6: =(A6-A13)/A13 -> 0.40710042 | C6: =C7*0.9 -> 119.57422
A7: =A8*105% -> 10298.863 | B7: =(A7-A13)/A13 -> 0.34009564 | C7: =C8*0.9 -> 132.86025
A8: =A9*105% -> 9808.4408 | B8: =(A8-A13)/A13 -> 0.27628156 | C8: =C9*0.9 -> 147.6225
A9: =A10*105% -> 9341.3722 | B9: =(A9-A13)/A13 -> 0.21550625 | C9: =C10*0.9 -> 164.025
A10: =A11*105% -> 8896.5449 | B10: =(A10-A13)/A13 -> 0.157625 | C10: =C11*0.9 -> 182.25
A11: =A12*105% -> 8472.8999 | B11: =(A11-A13)/A13 -> 0.1025 | C11: =C12*0.9 -> 202.5
A12: =A13*105% -> 8069.4285 | B12: =(A12-A13)/A13 -> 0.05 | C12: =C13*0.9 -> 225
A13: 7685.17 | B13: =(A13-A13)/A13 -> 0 | C13: 250
A14: =A13*0.95 -> 7300.9115 | B14: =(A14-A13)/A13 -> -0.05 | C14: =C13*1.1 -> 275
A15: =A13*0.9 -> 6916.653 | B15: =(A15-A13)/A13 -> -0.1 | C15: =C13*1.2 -> 300
A16: =A13*0.85 -> 6532.3945 | B16: =(A16-A13)/A13 -> -0.15 | C16: =C13*1.3 -> 325
A17: =A13*0.8 -> 6148.136 | B17: =(A17-A13)/A13 -> -0.2 | C17: =C13*1.4 -> 350
A18: =A13*0.75 -> 5763.8775 | B18: =(A18-A13)/A13 -> -0.25 | C18: =C13*1.5 -> 375
A19: =A13*0.7 -> 5379.619 | B19: =(A19-A13)/A13 -> -0.3 | C19: =C13*1.6 -> 400
A20: =A13*0.65 -> 4995.3605 | B20: =(A20-A13)/A13 -> -0.35 | C20: =C13*1.7 -> 425
A21: =A13*0.6 -> 4611.102 | B21: =(A21-A13)/A13 -> -0.4 | C21: =C13*1.8 -> 450
A22: =A13*0.55 -> 4226.8435 | B22: =(A22-A13)/A13 -> -0.45 | C22: =C13*1.9 -> 475
A23: =A13*0.5 -> 3842.585 | B23: =(A23-A13)/A13 -> -0.5 | C23: =C13*2 -> 500
A24: =A13*0.45 -> 3458.3265 | B24: =(A24-A13)/A13 -> -0.55 | C24: =C13*2.1 -> 525
A25: =A13*0.4 -> 3074.068 | B25: =(A25-A13)/A13 -> -0.6 | C25: =C13*2.2 -> 550
A26: =A13*0.35 -> 2689.8095 | B26: =(A26-A13)/A13 -> -0.65 | C26: =C13*2.3 -> 575
A30: 7685.17 | B30: =(A30-A30)/A30 -> 0 | C30: 2700 | E30: 0 | F30: 0
A31: =A30*0.95 -> 7300.9115 | B31: =(A31-A30)/A30 -> -0.05 | C31: =C30*1.1 -> 2970 | E31: =(A31-A30)/A30*C30 -> -135 | F31: =E31/SUM(C30:C31) -> -0.023809524
A32: =A30*0.9 -> 6916.653 | B32: =(A32-A30)/A30 -> -0.1 | C32: =C31*1.1 -> 3267 | E32: =(A32-A30)/A30*C30+(A32-A31)/A31*C31 -> -426.31579 | F32: =E32/SUM(C30:C32) -> -0.047702337
A33: =A30*0.85 -> 6532.3945 | B33: =(A33-A30)/A30 -> -0.15 | C33: =C32*1.1 -> 3593.7 | E33: =(A33-A30)/A30*C30+(A33-A31)/A31*C31+(A33-A32)/A32*C32 -> -899.13158 | F33: =E33/SUM(C30:C33) -> -0.071754298
A34: =A30*0.8 -> 6148.136 | B34: =(A34-A30)/A30 -> -0.2 | C34: =C33*1.1 -> 3953.07 | E34: =(A34-A30)/A30*C30+(A34-A31)/A31*C31+(A34-A32)/A32*C32+(A34-A33)/A33*C33 -> -1583.3415 | F34: =E34/SUM(C30:C34) -> -0.096054573
A35: =A30*0.75 -> 5763.8775 | B35: =(A35-A30)/A30 -> -0.25 | C35: =C34*1.1 -> 4348.377 | E35: =(A35-A30)/A30*C30+(A35-A31)/A31*C31+(A35-A32)/A32*C32+(A35-A33)/A33*C33+(A35-A34)/A34*C34 -> -2514.6183 | F35: =E35/SUM(C30:C35) -> -0.12070855
A36: =A30*0.7 -> 5379.619 | B36: =(A36-A30)/A30 -> -0.3 | C36: =C35*1.1 -> 4783.2147 | E36: =(A36-A30)/A30*C30+(A36-A31)/A31*C31+(A36-A32)/A32*C32+(A36-A33)/A33*C33+(A36-A34)/A34*C34+(A36-A35)/A35*C35 -> -3735.7869 | F36: =E36/SUM(C30:C36) -> -0.14584166
A37: =A30*0.65 -> 4995.3605 | B37: =(A37-A30)/A30 -> -0.35 | C37: =C36*1.1 -> 5261.5362 | E37: =(A37-A30)/A30*C30+(A37-A31)/A31*C31+(A37-A32)/A32*C32+(A37-A33)/A33*C33+(A37-A34)/A34*C34+(A37-A35)/A35*C35+(A37-A36)/A36*C36 -> -5298.6136 | F37: =E37/SUM(C30:C37) -> -0.17160447
A38: =A30*0.6 -> 4611.102 | B38: =(A38-A30)/A30 -> -0.4 | C38: =C37*1.1 -> 5787.6898 | E38: =(A38-A30)/A30*C30+(A38-A31)/A31*C31+(A38-A32)/A32*C32+(A38-A33)/A33*C33+(A38-A34)/A34*C34+(A38-A35)/A35*C35+(A38-A36)/A36*C36+(A38-A37)/A37*C37 -> -7266.174 | F38: =E38/SUM(C30:C38) -> -0.19817962
A39: =A30*0.55 -> 4226.8435 | B39: =(A39-A30)/A30 -> -0.45 | C39: =C38*1.1 -> 6366.4588 | E39: =(A39-A30)/A30*C30+(A39-A31)/A31*C31+(A39-A32)/A32*C32+(A39-A33)/A33*C33+(A39-A34)/A34*C34+(A39-A35)/A35*C35+(A39-A36)/A36*C36+(A39-A37)/A37*C37+(A39-A38)/A38*C38 -> -9716.0418 | F39: =E39/SUM(C30:C39) -> -0.22579144
C41: =SUM(C30:C39) -> 43031.046 | D41: =SUM(D30:D39) -> 0

Sheet 中证红利
D1: 43952
D2: PE 6.65/11.28%
D3: PB 0.76/0.08%
E4: 43986 | F4: 43993 | G4: 44022
A5: =A6*105% -> 6042.9701 | B5: =(A5-A13)/A13 -> 0.47745544 | C5: =C6*0.9 -> 172.18688
A6: =A7*105% -> 5755.2096 | B6: =(A6-A13)/A13 -> 0.40710042 | C6: =C7*0.9 -> 191.31876
A7: =A8*105% -> 5481.152 | B7: =(A7-A13)/A13 -> 0.34009564 | C7: =C8*0.9 -> 212.5764
A8: =A9*105% -> 5220.1447 | B8: =(A8-A13)/A13 -> 0.27628156 | C8: =C9*0.9 -> 236.196
A9: =A10*105% -> 4971.5664 | B9: =(A9-A13)/A13 -> 0.21550625 | C9: =C10*0.9 -> 262.44
A10: =A11*105% -> 4734.8252 | B10: =(A10-A13)/A13 -> 0.157625 | C10: =C11*0.9 -> 291.6
A11: =A12*105% -> 4509.3573 | B11: =(A11-A13)/A13 -> 0.1025 | C11: =C12*0.9 -> 324 | G11: 1000
A12: =A13*105% -> 4294.626 | B12: =(A12-A13)/A13 -> 0.05 | C12: =C13*0.9 -> 360
A13: 4090.12 | B13: =(A13-A13)/A13 -> 0 | C13: 400 | E13: 4104 | F13: 4043
A14: =A13*0.95 -> 3885.614 | B14: =(A14-A13)/A13 -> -0.05 | C14: =C13*1.1 -> 440
A15: =A13*0.9 -> 3681.108 | B15: =(A15-A13)/A13 -> -0.1 | C15: =C13*1.2 -> 480
A16: =A13*0.85 -> 3476.602 | B16: =(A16-A13)/A13 -> -0.15 | C16: =C13*1.3 -> 520
A17: =A13*0.8 -> 3272.096 | B17: =(A17-A13)/A13 -> -0.2 | C17: =C13*1.4 -> 560
A18: =A13*0.75 -> 3067.59 | B18: =(A18-A13)/A13 -> -0.25 | C18: =C13*1.5 -> 600
A19: =A13*0.7 -> 2863.084 | B19: =(A19-A13)/A13 -> -0.3 | C19: =C13*1.6 -> 640
A20: =A13*0.65 -> 2658.578 | B20: =(A20-A13)/A13 -> -0.35 | C20: =C13*1.7 -> 680
A21: =A13*0.6 -> 2454.072 | B21: =(A21-A13)/A13 -> -0.4 | C21: =C13*1.8 -> 720
A22: =A13*0.55 -> 2249.566 | B22: =(A22-A13)/A13 -> -0.45 | C22: =C13*1.9 -> 760
A23: =A13*0.5 -> 2045.06 | B23: =(A23-A13)/A13 -> -0.5 | C23: =C13*2 -> 800
A24: =A13*0.45 -> 1840.554 | B24: =(A24-A13)/A13 -> -0.55 | C24: =C13*2.1 -> 840
A25: =A13*0.4 -> 1636.048 | B25: =(A25-A13)/A13 -> -0.6 | C25: =C13*2.2 -> 880
A26: =A13*0.35 -> 1431.542 | B26: =(A26-A13)/A13 -> -0.65 | C26: =C13*2.3 -> 920
A30: 4090.12 | B30: =(A30-A30)/A30 -> 0 | C30: 1200 | D30: =C30 -> 1200 | E30: 0 | F30: 0
A31: =A30*0.95 -> 3885.614 | B31: =(A31-A30)/A30 -> -0.05 | C31: =C30*1.1 -> 1320 | E31: =(A31-A30)/A30*C30 -> -60 | F31: =E31/SUM(C30:C31) -> -0.023809524
A32: =A30*0.9 -> 3681.108 | B32: =(A32-A30)/A30 -> -0.1 | C32: =C31*1.1 -> 1452 | E32: =(A32-A30)/A30*C30+(A32-A31)/A31*C31 -> -189.47368 | F32: =E32/SUM(C30:C32) -> -0.047702337
A33: =A30*0.85 -> 3476.602 | B33: =(A33-A30)/A30 -> -0.15 | C33: =C32*1.1 -> 1597.2 | E33: =(A33-A30)/A30*C30+(A33-A31)/A31*C31+(A33-A32)/A32*C32 -> -399.61404 | F33: =E33/SUM(C30:C33) -> -0.071754298
A34: =A30*0.8 -> 3272.096 | B34: =(A34-A30)/A30 -> -0.2 | C34: =C33*1.1 -> 1756.92 | E34: =(A34-A30)/A30*C30+(A34-A31)/A31*C31+(A34-A32)/A32*C32+(A34-A33)/A33*C33 -> -703.70733 | F34: =E34/SUM(C30:C34) -> -0.096054573
A35: =A30*0.75 -> 3067.59 | B35: =(A35-A30)/A30 -> -0.25 | C35: =C34*1.1 -> 1932.612 | E35: =(A35-A30)/A30*C30+(A35-A31)/A31*C31+(A35-A32)/A32*C32+(A35-A33)/A33*C33+(A35-A34)/A34*C34 -> -1117.6081 | F35: =E35/SUM(C30:C35) -> -0.12070855
A36: =A30*0.7 -> 2863.084 | B36: =(A36-A30)/A30 -> -0.3 | C36: =C35*1.1 -> 2125.8732 | E36: =(A36-A30)/A30*C30+(A36-A31)/A31*C31+(A36-A32)/A32*C32+(A36-A33)/A33*C33+(A36-A34)/A34*C34+(A36-A35)/A35*C35 -> -1660.3497 | F36: =E36/SUM(C30:C36) -> -0.14584166
A37: =A30*0.65 -> 2658.578 | B37: =(A37-A30)/A30 -> -0.35 | C37: =C36*1.1 -> 2338.4605 | E37: =(A37-A30)/A30*C30+(A37-A31)/A31*C31+(A37-A32)/A32*C32+(A37-A33)/A33*C33+(A37-A34)/A34*C34+(A37-A35)/A35*C35+(A37-A36)/A36*C36 -> -2354.9394 | F37: =E37/SUM(C30:C37) -> -0.17160447
A38: =A30*0.6 -> 2454.072 | B38: =(A38-A30)/A30 -> -0.4 | C38: =C37*1.1 -> 2572.3066 | E38: =(A38-A30)/A30*C30+(A38-A31)/A31*C31+(A38-A32)/A32*C32+(A38-A33)/A33*C33+(A38-A34)/A34*C34+(A38-A35)/A35*C35+(A38-A36)/A36*C36+(A38-A37)/A37*C37 -> -3229.4106 | F38: =E38/SUM(C30:C38) -> -0.19817962
A39: =A30*0.55 -> 2249.566 | B39: =(A39-A30)/A30 -> -0.45 | C39: =C38*1.1 -> 2829.5372 | E39: =(A39-A30)/A30*C30+(A39-A31)/A31*C31+(A39-A32)/A32*C32+(A39-A33)/A33*C33+(A39-A34)/A34*C34+(A39-A35)/A35*C35+(A39-A36)/A36*C36+(A39-A37)/A37*C37+(A39-A38)/A38*C38 -> -4318.2408 | F39: =E39/SUM(C30:C39) -> -0.22579144
C41: =SUM(C30:C39) -> 19124.91 | D41: =SUM(D30:D39) -> 1200

Sheet 恒生指数
D1: 43952
D2: PE 6.65/11.28%
D3: PB 0.76/0.08%
